Workbook
Name address: 'Inputs'!$C$6:$C$6
Name zip: 'Inputs'!$C$7:$C$7
Name beds: 'Inputs'!$C$8:$C$8
Name baths: 'Inputs'!$C$9:$C$9
Name purchase_price: 'Inputs'!$C$12:$C$12
Name arv: 'Inputs'!$C$13:$C$13
Name rehab_cost: 'Inputs'!$C$14:$C$14
Name closing_cost_pct: 'Inputs'!$C$15:$C$15
Name holding_months: 'Inputs'!$C$16:$C$16
Name down_payment_pct: 'Inputs'!$C$19:$C$19
Name interest_rate: 'Inputs'!$C$20:$C$20
Name loan_term_yrs: 'Inputs'!$C$21:$C$21
Name refi_year: 'Inputs'!$C$24:$C$24
Name refi_ltv: 'Inputs'!$C$25:$C$25
Name refi_interest_rate: 'Inputs'!$C$26:$C$26
Name refi_term_yrs: 'Inputs'!$C$27:$C$27
Name refi_closing_cost_pct: 'Inputs'!$C$28:$C$28
Name monthly_rent: 'Inputs'!$C$31:$C$31
Name rent_growth: 'Inputs'!$C$32:$C$32
Name vacancy_rate: 'Inputs'!$C$33:$C$33
Name management_pct: 'Inputs'!$C$36:$C$36
Name maintenance_pct: 'Inputs'!$C$37:$C$37
Name capex_reserve_pct: 'Inputs'!$C$38:$C$38
Name property_tax_annual: 'Inputs'!$C$41:$C$41
Name insurance_annual: 'Inputs'!$C$42:$C$42
Name utilities_annual: 'Inputs'!$C$43:$C$43
Name hoa_annual: 'Inputs'!$C$44:$C$44
Name expense_growth: 'Inputs'!$C$45:$C$45
Name hold_period_yrs: 'Inputs'!$C$48:$C$48
Name exit_cap_rate: 'Inputs'!$C$49:$C$49
Name cost_of_sale_pct: 'Inputs'!$C$50:$C$50
Name cap_rate_min: 'Inputs'!$C$53:$C$53
Name cash_on_cash_min: 'Inputs'!$C$54:$C$54
Name dscr_min: 'Inputs'!$C$55:$C$55
Name irr_min: 'Inputs'!$C$56:$C$56
Name max_price_to_arv: 'Inputs'!$C$57:$C$57
Name cf_year_header_row: 'Cashflow'!$C$4:$C$4

Sheet Inputs
B1: Property Analysis — Inputs
B3: All inputs the model needs. Blue cells are editable. Skill writes only to this tab.
B5: Property
B6: Property Address
B7: ZIP Code
B8: Bedrooms | C8: 3
B9: Bathrooms | C9: 1
B11: Deal Particulars
B12: Purchase Price | C12: 130000
B13: ARV (After-Repair Value) | C13: 255000
B14: Rehab Cost | C14: 55000
B15: Closing Cost (% of price) | C15: 0.06
B16: Holding Period (months) | C16: 3
B18: Financing — Acquisition
B19: Down Payment (% of price) | C19: 1 | D19: 1.0 = all cash; 0.20 = 20% down
B20: Interest Rate | C20: 0.085
B21: Loan Term (yrs) | C21: 30
B23: Financing — Refinance (BRRRR)
B24: Refi Year (0 = no refi) | C24: 3
B25: Refi LTV (% of ARV) | C25: 0.75
B26: Refi Interest Rate | C26: 0.075
B27: Refi Term (yrs) | C27: 30
B28: Refi Closing Cost (% of loan) | C28: 0.04
B30: Operating — Rent
B31: Monthly Rent (FMR or override) | C31: 1670
B32: Annual Rent Growth | C32: 0.03 | D32: Section 8 follows HUD reset; 3% historical
B33: Vacancy Rate | C33: 0.04 | D33: Section 8 typically lower than market
B35: Operating — Variable Expenses (% of gross rent)
B36: Management Fee | C36: 0.1
B37: Maintenance Reserve | C37: 0.05
B38: CapEx Reserve | C38: 0.05
B40: Operating — Fixed Expenses (annual $)
B41: Property Tax (annual) | C41: 3249
B42: Insurance (annual) | C42: 1020
B43: Utilities (annual) | C43: 0 | D43: Section 8: often tenant-paid; leave 0
B44: HOA / Other (annual) | C44: 0
B45: Expense Growth Rate | C45: 0.03
B47: Exit
B48: Hold Period (yrs) | C48: 10
B49: Exit Cap Rate | C49: 0.08
...

Sheet Summary
B1: Property Analysis — Summary
B3: Address: | C3: =address
B4: ZIP: | C4: =zip
B5: Beds / Baths: | C5: =beds & " / " & baths
B7: Key Metrics
B8: Total Cash Invested | C8: =-'Cashflow'!C36 | E8: Year 1 NOI | F8: ='Cashflow'!D22
B9: Cap Rate (Y1 / Cash Invested) | C9: =IFERROR('Cashflow'!D22/(-'Cashflow'!C36),0) | E9: Cap Rate (Y1 / Purchase Price) | F9: =IFERROR('Cashflow'!D22/purchase_price,0)
B10: Y1 Cash-on-Cash | C10: =IFERROR(('Cashflow'!D22+'Cashflow'!D29)/(-'Cashflow'!C36),0) | E10: DSCR (Year 1) | F10: =IFERROR('Cashflow'!D37,"n/a")
B11: DSCR (Min Observed) | C11: =IF(COUNT('Cashflow'!D37:'Cashflow'!R37)=0,"n/a",MIN('Cashflow'!D37:'Cashflow'!R37)) | E11: Price / ARV | F11: =IFERROR(purchase_price/arv,0)
B14: Returns (10-Year Hold)
B15: Levered IRR | C15: =IFERROR(IRR('Cashflow'!C36:'Cashflow'!R36),0) | E15: Equity Multiple | F15: =IFERROR(SUMIF('Cashflow'!C36:'Cashflow'!R36,">0")/-SUMIF('Cashflow'!C36:'Cashflow'!R36,"<0"),0)
B16: Total Net Profit | C16: =SUM('Cashflow'!C36:'Cashflow'!R36) | E16: Year 10 Exit Value | F16: =IFERROR('Cashflow'!M34,0)
B19: Decision — Buy / No-Buy
B20: Metric | C20: Value | D20: Threshold | E20: Status
B21: Cap Rate (Y1) | C21: =IFERROR('Cashflow'!D22/(-'Cashflow'!C36),0) | D21: =cap_rate_min | E21: =IF(C21>=D21,"PASS","FAIL")
B22: Cash-on-Cash (Y1) | C22: =IFERROR(('Cashflow'!D22+'Cashflow'!D29)/(-'Cashflow'!C36),0) | D22: =cash_on_cash_min | E22: =IF(C22>=D22,"PASS","FAIL")
B23: DSCR (min) | C23: =IF(COUNT('Cashflow'!D37:'Cashflow'!R37)=0,9999,MIN('Cashflow'!D37:'Cashflow'!R37)) | D23: =dscr_min | E23: =IF(C23>=D23,"PASS","FAIL")
B24: Levered IRR | C24: =IFERROR(IRR('Cashflow'!C36:'Cashflow'!R36),0) | D24: =irr_min | E24: =IF(C24>=D24,"PASS","FAIL")
B25: Price / ARV | C25: =IFERROR(purchase_price/arv,0) | D25: =max_price_to_arv | E25: =IF(C25<=D25,"PASS","FAIL")
B27: Checks Passed | C27: =IF(E21="PASS",1,0)+IF(E22="PASS",1,0)+IF(E23="PASS",1,0)+IF(E24="PASS",1,0)+IF(E25="PASS",1,0)
B28: Checks Failed | C28: =IF(E21="FAIL",1,0)+IF(E22="FAIL",1,0)+IF(E23="FAIL",1,0)+IF(E24="FAIL",1,0)+IF(E25="FAIL",1,0)
B29: RECOMMENDATION | C29: =IF(C28=0,"BUY",IF(C28<=2,"CONSIDER","PASS"))

Sheet Cashflow
B1: Cashflow
B4: Year | C4: 0 | D4: 1 | E4: 2 | F4: 3 | G4: 4 | H4: 5 | I4: 6 | J4: 7 | K4: 8 | L4: 9 | M4: 10 | N4: 11 | O4: 12 | P4: 13 | Q4: 14 | R4: 15
B6: Revenue
B7: Gross Rent | C7: =IF(OR(C$4<1,C$4>hold_period_yrs),0,monthly_rent*12*(1+rent_growth)^(C$4-1)) | D7: =IF(OR(D$4<1,D$4>hold_period_yrs),0,monthly_rent*12*(1+rent_growth)^(D$4-1)) | E7: =IF(OR(E$4<1,E$4>hold_period_yrs),0,monthly_rent*12*(1+rent_growth)^(E$4-1)) | F7: =IF(OR(F$4<1,F$4>hold_period_yrs),0,monthly_rent*12*(1+rent_growth)^(F$4-1)) | G7: =IF(OR(G$4<1,G$4>hold_period_yrs),0,monthly_rent*12*(1+rent_growth)^(G$4-1)) | H7: =IF(OR(H$4<1,H$4>hold_period_yrs),0,monthly_rent*12*(1+rent_growth)^(H$4-1)) | I7: =IF(OR(I$4<1,I$4>hold_period_yrs),0,monthly_rent*12*(1+rent_growth)^(I$4-1)) | J7: =IF(OR(J$4<1,J$4>hold_period_yrs),0,monthly_rent*12*(1+rent_growth)^(J$4-1)) | ... R7: =IF(OR(R$4<1,R$4>hold_period_yrs),0,monthly_rent*12*(1+rent_growth)^(R$4-1))
B8: Vacancy Loss | C8: =IF(OR(C$4<1,C$4>hold_period_yrs),0,-C7*vacancy_rate) | D8: =IF(OR(D$4<1,D$4>hold_period_yrs),0,-D7*vacancy_rate) | E8: =IF(OR(E$4<1,E$4>hold_period_yrs),0,-E7*vacancy_rate) | F8: =IF(OR(F$4<1,F$4>hold_period_yrs),0,-F7*vacancy_rate) | G8: =IF(OR(G$4<1,G$4>hold_period_yrs),0,-G7*vacancy_rate) | H8: =IF(OR(H$4<1,H$4>hold_period_yrs),0,-H7*vacancy_rate) | I8: =IF(OR(I$4<1,I$4>hold_period_yrs),0,-I7*vacancy_rate) | J8: =IF(OR(J$4<1,J$4>hold_period_yrs),0,-J7*vacancy_rate) | ... R8: =IF(OR(R$4<1,R$4>hold_period_yrs),0,-R7*vacancy_rate)
B9: Effective Gross Income | C9: =IF(OR(C$4<1,C$4>hold_period_yrs),0,C7+C8) | D9: =IF(OR(D$4<1,D$4>hold_period_yrs),0,D7+D8) | E9: =IF(OR(E$4<1,E$4>hold_period_yrs),0,E7+E8) | F9: =IF(OR(F$4<1,F$4>hold_period_yrs),0,F7+F8) | G9: =IF(OR(G$4<1,G$4>hold_period_yrs),0,G7+G8) | H9: =IF(OR(H$4<1,H$4>hold_period_yrs),0,H7+H8) | I9: =IF(OR(I$4<1,I$4>hold_period_yrs),0,I7+I8) | J9: =IF(OR(J$4<1,J$4>hold_period_yrs),0,J7+J8) | ... R9: =IF(OR(R$4<1,R$4>hold_period_yrs),0,R7+R8)
B11: Operating Expenses — Variable
B12: Management | C12: =IF(OR(C$4<1,C$4>hold_period_yrs),0,-C7*management_pct) | D12: =IF(OR(D$4<1,D$4>hold_period_yrs),0,-D7*management_pct) | E12: =IF(OR(E$4<1,E$4>hold_period_yrs),0,-E7*management_pct) | F12: =IF(OR(F$4<1,F$4>hold_period_yrs),0,-F7*management_pct) | G12: =IF(OR(G$4<1,G$4>hold_period_yrs),0,-G7*management_pct) | H12: =IF(OR(H$4<1,H$4>hold_period_yrs),0,-H7*management_pct) | I12: =IF(OR(I$4<1,I$4>hold_period_yrs),0,-I7*management_pct) | J12: =IF(OR(J$4<1,J$4>hold_period_yrs),0,-J7*management_pct) | ... R12: =IF(OR(R$4<1,R$4>hold_period_yrs),0,-R7*management_pct)
B13: Maintenance | C13: =IF(OR(C$4<1,C$4>hold_period_yrs),0,-C7*maintenance_pct) | D13: =IF(OR(D$4<1,D$4>hold_period_yrs),0,-D7*maintenance_pct) | E13: =IF(OR(E$4<1,E$4>hold_period_yrs),0,-E7*maintenance_pct) | F13: =IF(OR(F$4<1,F$4>hold_period_yrs),0,-F7*maintenance_pct) | G13: =IF(OR(G$4<1,G$4>hold_period_yrs),0,-G7*maintenance_pct) | H13: =IF(OR(H$4<1,H$4>hold_period_yrs),0,-H7*maintenance_pct) | I13: =IF(OR(I$4<1,I$4>hold_period_yrs),0,-I7*maintenance_pct) | J13: =IF(OR(J$4<1,J$4>hold_period_yrs),0,-J7*maintenance_pct) | ... R13: =IF(OR(R$4<1,R$4>hold_period_yrs),0,-R7*maintenance_pct)
B14: CapEx Reserve | C14: =IF(OR(C$4<1,C$4>hold_period_yrs),0,-C7*capex_reserve_pct) | D14: =IF(OR(D$4<1,D$4>hold_period_yrs),0,-D7*capex_reserve_pct) | E14: =IF(OR(E$4<1,E$4>hold_period_yrs),0,-E7*capex_reserve_pct) | F14: =IF(OR(F$4<1,F$4>hold_period_yrs),0,-F7*capex_reserve_pct) | G14: =IF(OR(G$4<1,G$4>hold_period_yrs),0,-G7*capex_reserve_pct) | H14: =IF(OR(H$4<1,H$4>hold_period_yrs),0,-H7*capex_reserve_pct) | I14: =IF(OR(I$4<1,I$4>hold_period_yrs),0,-I7*capex_reserve_pct) | J14: =IF(OR(J$4<1,J$4>hold_period_yrs),0,-J7*capex_reserve_pct) | ... R14: =IF(OR(R$4<1,R$4>hold_period_yrs),0,-R7*capex_reserve_pct)
B16: Operating Expenses — Fixed
B17: Property Tax | C17: =IF(OR(C$4<1,C$4>hold_period_yrs),0,-property_tax_annual*(1+expense_growth)^(C$4-1)) | D17: =IF(OR(D$4<1,D$4>hold_period_yrs),0,-property_tax_annual*(1+expense_growth)^(D$4-1)) | E17: =IF(OR(E$4<1,E$4>hold_period_yrs),0,-property_tax_annual*(1+expense_growth)^(E$4-1)) | F17: =IF(OR(F$4<1,F$4>hold_period_yrs),0,-property_tax_annual*(1+expense_growth)^(F$4-1)) | G17: =IF(OR(G$4<1,G$4>hold_period_yrs),0,-property_tax_annual*(1+expense_growth)^(G$4-1)) | H17: =IF(OR(H$4<1,H$4>hold_period_yrs),0,-property_tax_annual*(1+expense_growth)^(H$4-1)) | I17: =IF(OR(I$4<1,I$4>hold_period_yrs),0,-property_tax_annual*(1+expense_growth)^(I$4-1)) | J17: =IF(OR(J$4<1,J$4>hold_period_yrs),0,-property_tax_annual*(1+expense_growth)^(J$4-1)) | ... R17: =IF(OR(R$4<1,R$4>hold_period_yrs),0,-property_tax_annual*(1+expense_growth)^(R$4-1))
B18: Insurance | C18: =IF(OR(C$4<1,C$4>hold_period_yrs),0,-insurance_annual*(1+expense_growth)^(C$4-1)) | D18: =IF(OR(D$4<1,D$4>hold_period_yrs),0,-insurance_annual*(1+expense_growth)^(D$4-1)) | E18: =IF(OR(E$4<1,E$4>hold_period_yrs),0,-insurance_annual*(1+expense_growth)^(E$4-1)) | F18: =IF(OR(F$4<1,F$4>hold_period_yrs),0,-insurance_annual*(1+expense_growth)^(F$4-1)) | G18: =IF(OR(G$4<1,G$4>hold_period_yrs),0,-insurance_annual*(1+expense_growth)^(G$4-1)) | H18: =IF(OR(H$4<1,H$4>hold_period_yrs),0,-insurance_annual*(1+expense_growth)^(H$4-1)) | I18: =IF(OR(I$4<1,I$4>hold_period_yrs),0,-insurance_annual*(1+expense_growth)^(I$4-1)) | J18: =IF(OR(J$4<1,J$4>hold_period_yrs),0,-insurance_annual*(1+expense_growth)^(J$4-1)) | ... R18: =IF(OR(R$4<1,R$4>hold_period_yrs),0,-insurance_annual*(1+expense_growth)^(R$4-1))
B19: Utilities | C19: =IF(OR(C$4<1,C$4>hold_period_yrs),0,-utilities_annual*(1+expense_growth)^(C$4-1)) | D19: =IF(OR(D$4<1,D$4>hold_period_yrs),0,-utilities_annual*(1+expense_growth)^(D$4-1)) | E19: =IF(OR(E$4<1,E$4>hold_period_yrs),0,-utilities_annual*(1+expense_growth)^(E$4-1)) | F19: =IF(OR(F$4<1,F$4>hold_period_yrs),0,-utilities_annual*(1+expense_growth)^(F$4-1)) | G19: =IF(OR(G$4<1,G$4>hold_period_yrs),0,-utilities_annual*(1+expense_growth)^(G$4-1)) | H19: =IF(OR(H$4<1,H$4>hold_period_yrs),0,-utilities_annual*(1+expense_growth)^(H$4-1)) | I19: =IF(OR(I$4<1,I$4>hold_period_yrs),0,-utilities_annual*(1+expense_growth)^(I$4-1)) | J19: =IF(OR(J$4<1,J$4>hold_period_yrs),0,-utilities_annual*(1+expense_growth)^(J$4-1)) | ... R19: =IF(OR(R$4<1,R$4>hold_period_yrs),0,-utilities_annual*(1+expense_growth)^(R$4-1))
B20: HOA / Other | C20: =IF(OR(C$4<1,C$4>hold_period_yrs),0,-hoa_annual*(1+expense_growth)^(C$4-1)) | D20: =IF(OR(D$4<1,D$4>hold_period_yrs),0,-hoa_annual*(1+expense_growth)^(D$4-1)) | E20: =IF(OR(E$4<1,E$4>hold_period_yrs),0,-hoa_annual*(1+expense_growth)^(E$4-1)) | F20: =IF(OR(F$4<1,F$4>hold_period_yrs),0,-hoa_annual*(1+expense_growth)^(F$4-1)) | G20: =IF(OR(G$4<1,G$4>hold_period_yrs),0,-hoa_annual*(1+expense_growth)^(G$4-1)) | H20: =IF(OR(H$4<1,H$4>hold_period_yrs),0,-hoa_annual*(1+expense_growth)^(H$4-1)) | I20: =IF(OR(I$4<1,I$4>hold_period_yrs),0,-hoa_annual*(1+expense_growth)^(I$4-1)) | J20: =IF(OR(J$4<1,J$4>hold_period_yrs),0,-hoa_annual*(1+expense_growth)^(J$4-1)) | ... R20: =IF(OR(R$4<1,R$4>hold_period_yrs),0,-hoa_annual*(1+expense_growth)^(R$4-1))
B22: Net Operating Income | C22: =IF(OR(C$4<1,C$4>hold_period_yrs),0,C9+C12+C13+C14+C17+C18+C19+C20) | D22: =IF(OR(D$4<1,D$4>hold_period_yrs),0,D9+D12+D13+D14+D17+D18+D19+D20) | E22: =IF(OR(E$4<1,E$4>hold_period_yrs),0,E9+E12+E13+E14+E17+E18+E19+E20) | F22: =IF(OR(F$4<1,F$4>hold_period_yrs),0,F9+F12+F13+F14+F17+F18+F19+F20) | G22: =IF(OR(G$4<1,G$4>hold_period_yrs),0,G9+G12+G13+G14+G17+G18+G19+G20) | H22: =IF(OR(H$4<1,H$4>hold_period_yrs),0,H9+H12+H13+H14+H17+H18+H19+H20) | I22: =IF(OR(I$4<1,I$4>hold_period_yrs),0,I9+I12+I13+I14+I17+I18+I19+I20) | J22: =IF(OR(J$4<1,J$4>hold_period_yrs),0,J9+J12+J13+J14+J17+J18+J19+J20) | ... R22: =IF(OR(R$4<1,R$4>hold_period_yrs),0,R9+R12+R13+R14+R17+R18+R19+R20)
B24: Debt Service
B25: Active Loan Principal | C25: =IF(OR(C$4<1,C$4>hold_period_yrs),0,IF(AND(refi_year>0,C$4>=refi_year),arv*refi_ltv,purchase_price*(1-down_payment_pct))) | D25: =IF(OR(D$4<1,D$4>hold_period_yrs),0,IF(AND(refi_year>0,D$4>=refi_year),arv*refi_ltv,purchase_price*(1-down_payment_pct))) | E25: =IF(OR(E$4<1,E$4>hold_period_yrs),0,IF(AND(refi_year>0,E$4>=refi_year),arv*refi_ltv,purchase_price*(1-down_payment_pct))) | F25: =IF(OR(F$4<1,F$4>hold_period_yrs),0,IF(AND(refi_year>0,F$4>=refi_year),arv*refi_ltv,purchase_price*(1-down_payment_pct))) | G25: =IF(OR(G$4<1,G$4>hold_period_yrs),0,IF(AND(refi_year>0,G$4>=refi_year),arv*refi_ltv,purchase_price*(1-down_payment_pct))) | H25: =IF(OR(H$4<1,H$4>hold_period_yrs),0,IF(AND(refi_year>0,H$4>=refi_year),arv*refi_ltv,purchase_price*(1-down_payment_pct))) | I25: =IF(OR(I$4<1,I$4>hold_period_yrs),0,IF(AND(refi_year>0,I$4>=refi_year),arv*refi_ltv,purchase_price*(1-down_payment_pct))) | J25: =IF(OR(J$4<1,J$4>hold_period_yrs),0,IF(AND(refi_year>0,J$4>=refi_year),arv*refi_ltv,purchase_price*(1-down_payment_pct))) | ... R25: =IF(OR(R$4<1,R$4>hold_period_yrs),0,IF(AND(refi_year>0,R$4>=refi_year),arv*refi_ltv,purchase_price*(1-down_payment_pct)))
B26: Active Interest Rate | C26: =IF(OR(C$4<1,C$4>hold_period_yrs),0,IF(AND(refi_year>0,C$4>=refi_year),refi_interest_rate,interest_rate)) | D26: =IF(OR(D$4<1,D$4>hold_period_yrs),0,IF(AND(refi_year>0,D$4>=refi_year),refi_interest_rate,interest_rate)) | E26: =IF(OR(E$4<1,E$4>hold_period_yrs),0,IF(AND(refi_year>0,E$4>=refi_year),refi_interest_rate,interest_rate)) | F26: =IF(OR(F$4<1,F$4>hold_period_yrs),0,IF(AND(refi_year>0,F$4>=refi_year),refi_interest_rate,interest_rate)) | G26: =IF(OR(G$4<1,G$4>hold_period_yrs),0,IF(AND(refi_year>0,G$4>=refi_year),refi_interest_rate,interest_rate)) | H26: =IF(OR(H$4<1,H$4>hold_period_yrs),0,IF(AND(refi_year>0,H$4>=refi_year),refi_interest_rate,interest_rate)) | I26: =IF(OR(I$4<1,I$4>hold_period_yrs),0,IF(AND(refi_year>0,I$4>=refi_year),refi_interest_rate,interest_rate)) | J26: =IF(OR(J$4<1,J$4>hold_period_yrs),0,IF(AND(refi_year>0,J$4>=refi_year),refi_interest_rate,interest_rate)) | ... R26: =IF(OR(R$4<1,R$4>hold_period_yrs),0,IF(AND(refi_year>0,R$4>=refi_year),refi_interest_rate,interest_rate))
B27: Active Loan Term (yrs) | C27: =IF(OR(C$4<1,C$4>hold_period_yrs),0,IF(AND(refi_year>0,C$4>=refi_year),refi_term_yrs,loan_term_yrs)) | D27: =IF(OR(D$4<1,D$4>hold_period_yrs),0,IF(AND(refi_year>0,D$4>=refi_year),refi_term_yrs,loan_term_yrs)) | E27: =IF(OR(E$4<1,E$4>hold_period_yrs),0,IF(AND(refi_year>0,E$4>=refi_year),refi_term_yrs,loan_term_yrs)) | F27: =IF(OR(F$4<1,F$4>hold_period_yrs),0,IF(AND(refi_year>0,F$4>=refi_year),refi_term_yrs,loan_term_yrs)) | G27: =IF(OR(G$4<1,G$4>hold_period_yrs),0,IF(AND(refi_year>0,G$4>=refi_year),refi_term_yrs,loan_term_yrs)) | H27: =IF(OR(H$4<1,H$4>hold_period_yrs),0,IF(AND(refi_year>0,H$4>=refi_year),refi_term_yrs,loan_term_yrs)) | I27: =IF(OR(I$4<1,I$4>hold_period_yrs),0,IF(AND(refi_year>0,I$4>=refi_year),refi_term_yrs,loan_term_yrs)) | J27: =IF(OR(J$4<1,J$4>hold_period_yrs),0,IF(AND(refi_year>0,J$4>=refi_year),refi_term_yrs,loan_term_yrs)) | ... R27: =IF(OR(R$4<1,R$4>hold_period_yrs),0,IF(AND(refi_year>0,R$4>=refi_year),refi_term_yrs,loan_term_yrs))
B28: Monthly Payment | C28: =IF(OR(C$4<1,C$4>hold_period_yrs),0,IFERROR(-PMT(C26/12,C27*12,C25),0)) | D28: =IF(OR(D$4<1,D$4>hold_period_yrs),0,IFERROR(-PMT(D26/12,D27*12,D25),0)) | E28: =IF(OR(E$4<1,E$4>hold_period_yrs),0,IFERROR(-PMT(E26/12,E27*12,E25),0)) | F28: =IF(OR(F$4<1,F$4>hold_period_yrs),0,IFERROR(-PMT(F26/12,F27*12,F25),0)) | G28: =IF(OR(G$4<1,G$4>hold_period_yrs),0,IFERROR(-PMT(G26/12,G27*12,G25),0)) | H28: =IF(OR(H$4<1,H$4>hold_period_yrs),0,IFERROR(-PMT(H26/12,H27*12,H25),0)) | I28: =IF(OR(I$4<1,I$4>hold_period_yrs),0,IFERROR(-PMT(I26/12,I27*12,I25),0)) | J28: =IF(OR(J$4<1,J$4>hold_period_yrs),0,IFERROR(-PMT(J26/12,J27*12,J25),0)) | ... R28: =IF(OR(R$4<1,R$4>hold_period_yrs),0,IFERROR(-PMT(R26/12,R27*12,R25),0))
B29: Annual Debt Service | C29: =IF(OR(C$4<1,C$4>hold_period_yrs),0,-C28*12) | D29: =IF(OR(D$4<1,D$4>hold_period_yrs),0,-D28*12) | E29: =IF(OR(E$4<1,E$4>hold_period_yrs),0,-E28*12) | F29: =IF(OR(F$4<1,F$4>hold_period_yrs),0,-F28*12) | G29: =IF(OR(G$4<1,G$4>hold_period_yrs),0,-G28*12) | H29: =IF(OR(H$4<1,H$4>hold_period_yrs),0,-H28*12) | I29: =IF(OR(I$4<1,I$4>hold_period_yrs),0,-I28*12) | J29: =IF(OR(J$4<1,J$4>hold_period_yrs),0,-J28*12) | ... R29: =IF(OR(R$4<1,R$4>hold_period_yrs),0,-R28*12)
B31: Capital Flows
B32: Acquisition Cost | C32: =IF(C$4=0,-(purchase_price*down_payment_pct+purchase_price*closing_cost_pct+rehab_cost+(C28*holding_months)),0) | D32: =IF(D$4=0,-(purchase_price*down_payment_pct+purchase_price*closing_cost_pct+rehab_cost+(D28*holding_months)),0) | E32: =IF(E$4=0,-(purchase_price*down_payment_pct+purchase_price*closing_cost_pct+rehab_cost+(E28*holding_months)),0) | F32: =IF(F$4=0,-(purchase_price*down_payment_pct+purchase_price*closing_cost_pct+rehab_cost+(F28*holding_months)),0) | G32: =IF(G$4=0,-(purchase_price*down_payment_pct+purchase_price*closing_cost_pct+rehab_cost+(G28*holding_months)),0) | H32: =IF(H$4=0,-(purchase_price*down_payment_pct+purchase_price*closing_cost_pct+rehab_cost+(H28*holding_months)),0) | I32: =IF(I$4=0,-(purchase_price*down_payment_pct+purchase_price*closing_cost_pct+rehab_cost+(I28*holding_months)),0) | J32: =IF(J$4=0,-(purchase_price*down_payment_pct+purchase_price*closing_cost_pct+rehab_cost+(J28*holding_months)),0) | ... R32: =IF(R$4=0,-(purchase_price*down_payment_pct+purchase_price*closing_cost_pct+rehab_cost+(R28*holding_months)),0)
B33: Refi Cash-Out | C33: =IF(AND(refi_year>0,C$4=refi_year),(arv*refi_ltv) - IFERROR(ABS(FV(interest_rate/12,refi_year*12,-(IFERROR(-PMT(interest_rate/12,loan_term_yrs*12,purchase_price*(1-down_payment_pct)),0)),purchase_price*(1-down_payment_pct))),purchase_price*(1-down_payment_pct)) - (arv*refi_ltv*refi_closing_cost_pct),0) | D33: =IF(AND(refi_year>0,D$4=refi_year),(arv*refi_ltv) - IFERROR(ABS(FV(interest_rate/12,refi_year*12,-(IFERROR(-PMT(interest_rate/12,loan_term_yrs*12,purchase_price*(1-down_payment_pct)),0)),purchase_price*(1-down_payment_pct))),purchase_price*(1-down_payment_pct)) - (arv*refi_ltv*refi_closing_cost_pct),0) | E33: =IF(AND(refi_year>0,E$4=refi_year),(arv*refi_ltv) - IFERROR(ABS(FV(interest_rate/12,refi_year*12,-(IFERROR(-PMT(interest_rate/12,loan_term_yrs*12,purchase_price*(1-down_payment_pct)),0)),purchase_price*(1-down_payment_pct))),purchase_price*(1-down_payment_pct)) - (arv*refi_ltv*refi_closing_cost_pct),0) | F33: =IF(AND(refi_year>0,F$4=refi_year),(arv*refi_ltv) - IFERROR(ABS(FV(interest_rate/12,refi_year*12,-(IFERROR(-PMT(interest_rate/12,loan_term_yrs*12,purchase_price*(1-down_payment_pct)),0)),purchase_price*(1-down_payment_pct))),purchase_price*(1-down_payment_pct)) - (arv*refi_ltv*refi_closing_cost_pct),0) | G33: =IF(AND(refi_year>0,G$4=refi_year),(arv*refi_ltv) - IFERROR(ABS(FV(interest_rate/12,refi_year*12,-(IFERROR(-PMT(interest_rate/12,loan_term_yrs*12,purchase_price*(1-down_payment_pct)),0)),purchase_price*(1-down_payment_pct))),purchase_price*(1-down_payment_pct)) - (arv*refi_ltv*refi_closing_cost_pct),0) | H33: =IF(AND(refi_year>0,H$4=refi_year),(arv*refi_ltv) - IFERROR(ABS(FV(interest_rate/12,refi_year*12,-(IFERROR(-PMT(interest_rate/12,loan_term_yrs*12,purchase_price*(1-down_payment_pct)),0)),purchase_price*(1-down_payment_pct))),purchase_price*(1-down_payment_pct)) - (arv*refi_ltv*refi_closing_cost_pct),0) | I33: =IF(AND(refi_year>0,I$4=refi_year),(arv*refi_ltv) - IFERROR(ABS(FV(interest_rate/12,refi_year*12,-(IFERROR(-PMT(interest_rate/12,loan_term_yrs*12,purchase_price*(1-down_payment_pct)),0)),purchase_price*(1-down_payment_pct))),purchase_price*(1-down_payment_pct)) - (arv*refi_ltv*refi_closing_cost_pct),0) | J33: =IF(AND(refi_year>0,J$4=refi_year),(arv*refi_ltv) - IFERROR(ABS(FV(interest_rate/12,refi_year*12,-(IFERROR(-PMT(interest_rate/12,loan_term_yrs*12,purchase_price*(1-down_payment_pct)),0)),purchase_price*(1-down_payment_pct))),purchase_price*(1-down_payment_pct)) - (arv*refi_ltv*refi_closing_cost_pct),0) | ... R33: =IF(AND(refi_year>0,R$4=refi_year),(arv*refi_ltv) - IFERROR(ABS(FV(interest_rate/12,refi_year*12,-(IFERROR(-PMT(interest_rate/12,loan_term_yrs*12,purchase_price*(1-down_payment_pct)),0)),purchase_price*(1-down_payment_pct))),purchase_price*(1-down_payment_pct)) - (arv*refi_ltv*refi_closing_cost_pct),0)
B34: Exit Proceeds (Net) | C34: =IF(C$4=hold_period_yrs,(C22*(1+rent_growth)/exit_cap_rate)*(1-cost_of_sale_pct) - IFERROR(ABS(FV(C26/12,IF(refi_year>0,hold_period_yrs-refi_year+1,hold_period_yrs)*12,-C28,C25)),0),0) | D34: =IF(D$4=hold_period_yrs,(D22*(1+rent_growth)/exit_cap_rate)*(1-cost_of_sale_pct) - IFERROR(ABS(FV(D26/12,IF(refi_year>0,hold_period_yrs-refi_year+1,hold_period_yrs)*12,-D28,D25)),0),0) | E34: =IF(E$4=hold_period_yrs,(E22*(1+rent_growth)/exit_cap_rate)*(1-cost_of_sale_pct) - IFERROR(ABS(FV(E26/12,IF(refi_year>0,hold_period_yrs-refi_year+1,hold_period_yrs)*12,-E28,E25)),0),0) | F34: =IF(F$4=hold_period_yrs,(F22*(1+rent_growth)/exit_cap_rate)*(1-cost_of_sale_pct) - IFERROR(ABS(FV(F26/12,IF(refi_year>0,hold_period_yrs-refi_year+1,hold_period_yrs)*12,-F28,F25)),0),0) | G34: =IF(G$4=hold_period_yrs,(G22*(1+rent_growth)/exit_cap_rate)*(1-cost_of_sale_pct) - IFERROR(ABS(FV(G26/12,IF(refi_year>0,hold_period_yrs-refi_year+1,hold_period_yrs)*12,-G28,G25)),0),0) | H34: =IF(H$4=hold_period_yrs,(H22*(1+rent_growth)/exit_cap_rate)*(1-cost_of_sale_pct) - IFERROR(ABS(FV(H26/12,IF(refi_year>0,hold_period_yrs-refi_year+1,hold_period_yrs)*12,-H28,H25)),0),0) | I34: =IF(I$4=hold_period_yrs,(I22*(1+rent_growth)/exit_cap_rate)*(1-cost_of_sale_pct) - IFERROR(ABS(FV(I26/12,IF(refi_year>0,hold_period_yrs-refi_year+1,hold_period_yrs)*12,-I28,I25)),0),0) | J34: =IF(J$4=hold_period_yrs,(J22*(1+rent_growth)/exit_cap_rate)*(1-cost_of_sale_pct) - IFERROR(ABS(FV(J26/12,IF(refi_year>0,hold_period_yrs-refi_year+1,hold_period_yrs)*12,-J28,J25)),0),0) | ... R34: =IF(R$4=hold_period_yrs,(R22*(1+rent_growth)/exit_cap_rate)*(1-cost_of_sale_pct) - IFERROR(ABS(FV(R26/12,IF(refi_year>0,hold_period_yrs-refi_year+1,hold_period_yrs)*12,-R28,R25)),0),0)
B36: Net Cash Flow | C36: =IF(C$4>hold_period_yrs,0,C22+C29+C32+C33+C34) | D36: =IF(D$4>hold_period_yrs,0,D22+D29+D32+D33+D34) | E36: =IF(E$4>hold_period_yrs,0,E22+E29+E32+E33+E34) | F36: =IF(F$4>hold_period_yrs,0,F22+F29+F32+F33+F34) | G36: =IF(G$4>hold_period_yrs,0,G22+G29+G32+G33+G34) | H36: =IF(H$4>hold_period_yrs,0,H22+H29+H32+H33+H34) | I36: =IF(I$4>hold_period_yrs,0,I22+I29+I32+I33+I34) | J36: =IF(J$4>hold_period_yrs,0,J22+J29+J32+J33+J34) | ... R36: =IF(R$4>hold_period_yrs,0,R22+R29+R32+R33+R34)
B37: DSCR | C37: =IF(OR(C$4<1,C$4>hold_period_yrs,C29=0),"",IFERROR(C22/-C29,"")) | D37: =IF(OR(D$4<1,D$4>hold_period_yrs,D29=0),"",IFERROR(D22/-D29,"")) | E37: =IF(OR(E$4<1,E$4>hold_period_yrs,E29=0),"",IFERROR(E22/-E29,"")) | F37: =IF(OR(F$4<1,F$4>hold_period_yrs,F29=0),"",IFERROR(F22/-F29,"")) | G37: =IF(OR(G$4<1,G$4>hold_period_yrs,G29=0),"",IFERROR(G22/-G29,"")) | H37: =IF(OR(H$4<1,H$4>hold_period_yrs,H29=0),"",IFERROR(H22/-H29,"")) | I37: =IF(OR(I$4<1,I$4>hold_period_yrs,I29=0),"",IFERROR(I22/-I29,"")) | J37: =IF(OR(J$4<1,J$4>hold_period_yrs,J29=0),"",IFERROR(J22/-J29,"")) | ... R37: =IF(OR(R$4<1,R$4>hold_period_yrs,R29=0),"",IFERROR(R22/-R29,""))

Sheet Audit
B1: Audit Checks
B3: Check | C3: Expected | D3: Actual | E3: Status | F3: Notes
B4: A. Workbook Health
B5: Purchase price is positive | C5: >0 | D5: =purchase_price | E5: =IF(purchase_price>0,"PASS","FAIL") | F5: Purchase price must be a positive number.
B6: ARV is positive | C6: >0 | D6: =arv | E6: =IF(arv>0,"PASS","FAIL") | F6: After-repair value must be a positive number.
B7: Monthly rent is positive | C7: >0 | D7: =monthly_rent | E7: =IF(monthly_rent>0,"PASS","FAIL") | F7: Rent must be > 0 for the model to produce returns.
B8: Hold period is at least 1 year | C8: >=1 | D8: =hold_period_yrs | E8: =IF(hold_period_yrs>=1,"PASS","FAIL") | F8: Cannot model a zero-year hold.
B9: Down payment between 0 and 100% | C9: 0 to 1 | D9: =down_payment_pct | E9: =IF(AND(down_payment_pct>=0,down_payment_pct<=1),"PASS","FAIL") | F9: 1.0 = all cash; 0.20 = 20% down. Anything outside [0,1] is an error.
B11: B. Sign Convention
B12: Year 1 Gross Rent is positive | C12: >0 | D12: ='Cashflow'!D7 | E12: =IF('Cashflow'!D7>0,"PASS","FAIL") | F12: Rent must come through as positive cash flow.
B13: Year 1 Property Tax is negative | C13: <0 | D13: ='Cashflow'!D17 | E13: =IF('Cashflow'!D17<=0,"PASS","FAIL") | F13: Expenses display as negative.
B14: Year 1 Debt Service is negative or zero | C14: <=0 | D14: ='Cashflow'!D29 | E14: =IF('Cashflow'!D29<=0,"PASS","FAIL") | F14: Debt payments are cash outflows.
B16: C. Tie-Outs
B17: Year 1 NOI ties to EGI + OpEx | C17: =ROUND('Cashflow'!D9+'Cashflow'!D12+'Cashflow'!D13+'Cashflow'!D14+'Cashflow'!D17+'Cashflow'!D18+'Cashflow'!D19+'Cashflow'!D20,2) | D17: =ROUND('Cashflow'!D22,2) | E17: =IF(ROUND('Cashflow'!D22,2)=ROUND('Cashflow'!D9+'Cashflow'!D12+'Cashflow'!D13+'Cashflow'!D14+'Cashflow'!D17+'Cashflow'!D18+'Cashflow'!D19+'Cashflow'!D20,2),"PASS","FAIL") | F17: Year 1 NOI must equal EGI plus all operating expenses.
B18: Year 0 acquisition cash matches inputs | C18: =-(purchase_price*down_payment_pct + purchase_price*closing_cost_pct + rehab_cost + IFERROR(-PMT(interest_rate/12,loan_term_yrs*12,purchase_price*(1-down_payment_pct)),0)*holding_months) | D18: ='Cashflow'!C32 | E18: =IF(ROUND('Cashflow'!C32,2)=ROUND(-(purchase_price*down_payment_pct+purchase_price*closing_cost_pct+rehab_cost+IFERROR(-PMT(interest_rate/12,loan_term_yrs*12,purchase_price*(1-down_payment_pct)),0)*holding_months),2),"PASS","FAIL") | F18: Year 0 outflow should equal down + closing + rehab + holding cost.
B20: D. Threshold Sanity
B21: Cap rate threshold is reasonable (3-15%) | C21: 0.03 to 0.15 | D21: =cap_rate_min | E21: =IF(AND(cap_rate_min>=0.03,cap_rate_min<=0.15),"PASS","WARN") | F21: Most SFH investors target 7-10%.
B22: DSCR threshold is reasonable (1.0-1.5x) | C22: 1.0 to 1.5 | D22: =dscr_min | E22: =IF(AND(dscr_min>=1.0,dscr_min<=1.5),"PASS","WARN") | F22: Lenders typically require 1.20-1.25x DSCR.
