Workbook
Name address: 'Inputs'!$C$7:$C$7
Name zip: 'Inputs'!$C$8:$C$8
Name beds: 'Inputs'!$C$9:$C$9
Name baths: 'Inputs'!$C$10:$C$10
Name beds_source: 'Inputs'!$C$11:$C$11
Name purchase_price: 'Inputs'!$C$14:$C$14
Name purchase_price_source: 'Inputs'!$C$15:$C$15
Name arv: 'Inputs'!$C$16:$C$16
Name arv_source: 'Inputs'!$C$17:$C$17
Name rehab_cost: 'Inputs'!$C$18:$C$18
Name closing_cost_pct: 'Inputs'!$C$19:$C$19
Name holding_months: 'Inputs'!$C$20:$C$20
Name wholesaler_fee: 'Inputs'!$C$23:$C$23
Name inspection_fee: 'Inputs'!$C$24:$C$24
Name appraisal_fee: 'Inputs'!$C$25:$C$25
Name holding_utilities_monthly: 'Inputs'!$C$26:$C$26
Name down_payment_pct: 'Inputs'!$C$29:$C$29
Name interest_rate: 'Inputs'!$C$30:$C$30
Name loan_term_yrs: 'Inputs'!$C$31:$C$31
Name refi_year: 'Inputs'!$C$34:$C$34
Name refi_ltv: 'Inputs'!$C$35:$C$35
Name refi_interest_rate: 'Inputs'!$C$36:$C$36
Name refi_term_yrs: 'Inputs'!$C$37:$C$37
Name refi_closing_cost_pct: 'Inputs'!$C$38:$C$38
Name monthly_rent: 'Inputs'!$C$41:$C$41
Name monthly_rent_source: 'Inputs'!$C$42:$C$42
Name market_rent: 'Inputs'!$C$43:$C$43
Name market_rent_source: 'Inputs'!$C$44:$C$44
Name rent_growth: 'Inputs'!$C$45:$C$45
Name vacancy_rate: 'Inputs'!$C$46:$C$46
Name management_pct: 'Inputs'!$C$49:$C$49
Name maintenance_pct: 'Inputs'!$C$50:$C$50
Name capex_reserve_pct: 'Inputs'!$C$51:$C$51
Name property_tax_annual: 'Inputs'!$C$54:$C$54
Name property_tax_source: 'Inputs'!$C$55:$C$55
Name insurance_annual: 'Inputs'!$C$56:$C$56
Name insurance_source: 'Inputs'!$C$57:$C$57
Name utilities_annual: 'Inputs'!$C$58:$C$58
Name hoa_annual: 'Inputs'!$C$59:$C$59
Name expense_growth: 'Inputs'!$C$60:$C$60
Name hold_period_yrs: 'Inputs'!$C$63:$C$63
Name exit_cap_rate: 'Inputs'!$C$64:$C$64
Name cost_of_sale_pct: 'Inputs'!$C$65:$C$65
Name appreciation_rate: 'Inputs'!$C$66:$C$66
Name gp_lp_split_lp: 'Inputs'!$C$69:$C$69
Name cap_rate_min: 'Inputs'!$C$72:$C$72
Name cash_on_cash_min: 'Inputs'!$C$73:$C$73
Name dscr_min: 'Inputs'!$C$74:$C$74
Name irr_min: 'Inputs'!$C$75:$C$75
Name max_price_to_arv: 'Inputs'!$C$76:$C$76
Name cf_year_header_row: 'Cashflow'!$C$4:$C$4

Sheet Summary
B1: Property Analysis — Summary
B3: Address: | C3: =address | F3: Beds / Baths: | G3: =beds & " / " & baths
B4: ZIP: | C4: =zip | F4: Hold Period: | G4: =hold_period_yrs & " years"
B6: Headline Metrics
B7: Cap Rate (Y1) | D7: DSCR (Y1) | F7: Levered IRR | G7: Equity Multiple
B8: =IFERROR('Cashflow'!D22/purchase_price,0) | D8: =IFERROR('Cashflow'!D39,"n/a") | F8: =IFERROR(IRR('Cashflow'!C38:'Cashflow'!R38),0) | G8: =IFERROR(SUMIF('Cashflow'!C38:'Cashflow'!R38,">0")/-SUMIF('Cashflow'!C38:'Cashflow'!R38,"<0"),0)
B10: VERDICT | C10: =IF((IF(IFERROR('Cashflow'!D22/purchase_price,0)>=cap_rate_min,1,0)+IF(IFERROR(('Cashflow'!D22+'Cashflow'!D29)/(-'Cashflow'!C38),0)>=cash_on_cash_min,1,0)+IF(IF(COUNT('Cashflow'!D39:'Cashflow'!R39)=0,9999,MIN('Cashflow'!D39:'Cashflow'!R39))>=dscr_min,1,0)+IF(IFERROR(IRR('Cashflow'!C38:'Cashflow'!R38),0)>=irr_min,1,0)+IF(IFERROR(purchase_price/arv,0)<=max_price_to_arv,1,0))=5,"BUY",IF((IF(IFERROR('Cashflow'!D22/purchase_price,0)>=cap_rate_min,1,0)+IF(IFERROR(('Cashflow'!D22+'Cashflow'!D29)/(-'Cashflow'!C38),0)>=cash_on_cash_min,1,0)+IF(IF(COUNT('Cashflow'!D39:'Cashflow'!R39)=0,9999,MIN('Cashflow'!D39:'Cashflow'!R39))>=dscr_min,1,0)+IF(IFERROR(IRR('Cashflow'!C38:'Cashflow'!R38),0)>=irr_min,1,0)+IF(IFERROR(purchase_price/arv,0)<=max_price_to_arv,1,0))>=3,"CONSIDER","PASS"))
B12: ORIGINAL PURCHASE | F12: POST REFI
B14: Acquisition Assumptions | F14: Acquisition Assumptions (Refi)
B15: Purchase Price | C15: =purchase_price | F15: Refi Price (= ARV) | G15: =arv
B16: Wholesaler Fee | C16: =wholesaler_fee | F16: Refi LTV | G16: =refi_ltv
B17: Total Purchase Price | C17: =purchase_price+wholesaler_fee | F17: Refi Loan Amount | G17: =arv*refi_ltv
B18: Rehab Cost | C18: =rehab_cost | F18: Refi Closing Cost | G18: =arv*refi_ltv*refi_closing_cost_pct
B19: Closing Cost | C19: =purchase_price*closing_cost_pct | F19: Mortgage Paid Off | G19: =IFERROR(ABS(FV(interest_rate/12,refi_year*12,-IFERROR(-PMT(interest_rate/12,loan_term_yrs*12,purchase_price*(1-down_payment_pct)),0),purchase_price*(1-down_payment_pct))),0)
B20: Holding Cost | C20: =(IFERROR(-PMT(interest_rate/12,loan_term_yrs*12,purchase_price*(1-down_payment_pct)),0)+property_tax_annual/12+insurance_annual/12+holding_utilities_monthly+utilities_annual/12)*holding_months | F20: Refi Cash to Owner | G20: =arv*refi_ltv - IFERROR(ABS(FV(interest_rate/12,refi_year*12,-IFERROR(-PMT(interest_rate/12,loan_term_yrs*12,purchase_price*(1-down_payment_pct)),0),purchase_price*(1-down_payment_pct))),0) - (arv*refi_ltv*refi_closing_cost_pct)
B21: First-Year Insurance | C21: =insurance_annual | F21: LP Capital Remaining | G21: =MAX(0,C24-G20)
B22: Inspection Fee | C22: =inspection_fee | F22: % LP Capital Returned | G22: =IFERROR(MIN(1,G20/C24),0)
B23: Appraisal Fee | C23: =appraisal_fee | F23: LP Capital Remaining % | G23: =1-G22
B24: LP Initial Investment | C24: =SUM(C15:C23) | F24: GP/LP Split (post-LP-return) | G24: =TEXT(gp_lp_split_lp,"0%")&" LP / "&TEXT(1-gp_lp_split_lp,"0%")&" GP"
B25: GP/LP Split (after capital returned) | C25: =TEXT(gp_lp_split_lp,"0%")&" LP / "&TEXT(1-gp_lp_split_lp,"0%")&" GP"
B27: Mortgage Calculator | F27: Mortgage Calculator (Refi)
B28: Down Payment (%) | C28: =down_payment_pct | F28: Refi LTV | G28: =refi_ltv
B29: Down Payment ($) | C29: =purchase_price*down_payment_pct | F29: Down Payment ($) | G29: =0
B30: Mortgage Amount | C30: =purchase_price*(1-down_payment_pct) | F30: Mortgage Amount | G30: =arv*refi_ltv
B31: Interest Rate | C31: =interest_rate | F31: Interest Rate | G31: =refi_interest_rate
B32: Term (yrs) | C32: =loan_term_yrs | F32: Term (yrs) | G32: =refi_term_yrs
B33: Monthly Payment | C33: =IFERROR(-PMT(interest_rate/12,loan_term_yrs*12,purchase_price*(1-down_payment_pct)),0) | F33: Monthly Payment | G33: =IFERROR(-PMT(refi_interest_rate/12,refi_term_yrs*12,arv*refi_ltv),0)
B34: Annual Debt Service | C34: =IFERROR(-PMT(interest_rate/12,loan_term_yrs*12,purchase_price*(1-down_payment_pct)),0)*12 | F34: Annual Debt Service | G34: =IFERROR(-PMT(refi_interest_rate/12,refi_term_yrs*12,arv*refi_ltv),0)*12
B36: Stabilized Proforma (Year 1) | F36: Stabilized Proforma (Year-After-Refi)
C37: Monthly | D37: Annual | G37: Monthly | H37: Annual
B38: Rental Income (Gross) | C38: =D38/12 | D38: ='Cashflow'!D7 | F38: Rental Income (Gross) | G38: =H38/12 | H38: =INDEX('Cashflow'!C7:'Cashflow'!R7,IF(refi_year>0,MIN(refi_year+2,hold_period_yrs+1),2))
B39: Vacancy | C39: =D39/12 | D39: ='Cashflow'!D8 | F39: Vacancy | G39: =H39/12 | H39: =INDEX('Cashflow'!C8:'Cashflow'!R8,IF(refi_year>0,MIN(refi_year+2,hold_period_yrs+1),2))
B40: Effective Gross Income | C40: =D40/12 | D40: ='Cashflow'!D9 | F40: Effective Gross Income | G40: =H40/12 | H40: =INDEX('Cashflow'!C9:'Cashflow'!R9,IF(refi_year>0,MIN(refi_year+2,hold_period_yrs+1),2))
B41: Property Tax | C41: =D41/12 | D41: ='Cashflow'!D17 | F41: Property Tax | G41: =H41/12 | H41: =INDEX('Cashflow'!C17:'Cashflow'!R17,IF(refi_year>0,MIN(refi_year+2,hold_period_yrs+1),2))
B42: Insurance | C42: =D42/12 | D42: ='Cashflow'!D18 | F42: Insurance | G42: =H42/12 | H42: =INDEX('Cashflow'!C18:'Cashflow'!R18,IF(refi_year>0,MIN(refi_year+2,hold_period_yrs+1),2))
B43: Utilities | C43: =D43/12 | D43: ='Cashflow'!D19 | F43: Utilities | G43: =H43/12 | H43: =INDEX('Cashflow'!C19:'Cashflow'!R19,IF(refi_year>0,MIN(refi_year+2,hold_period_yrs+1),2))
B44: Management | C44: =D44/12 | D44: ='Cashflow'!D12 | F44: Management | G44: =H44/12 | H44: =INDEX('Cashflow'!C12:'Cashflow'!R12,IF(refi_year>0,MIN(refi_year+2,hold_period_yrs+1),2))
B45: Maintenance | C45: =D45/12 | D45: ='Cashflow'!D13 | F45: Maintenance | G45: =H45/12 | H45: =INDEX('Cashflow'!C13:'Cashflow'!R13,IF(refi_year>0,MIN(refi_year+2,hold_period_yrs+1),2))
B46: CapEx Reserve | C46: =D46/12 | D46: ='Cashflow'!D14 | F46: CapEx Reserve | G46: =H46/12 | H46: =INDEX('Cashflow'!C14:'Cashflow'!R14,IF(refi_year>0,MIN(refi_year+2,hold_period_yrs+1),2))
B47: Net Operating Income | C47: =D47/12 | D47: ='Cashflow'!D22 | F47: Net Operating Income | G47: =H47/12 | H47: =INDEX('Cashflow'!C22:'Cashflow'!R22,IF(refi_year>0,MIN(refi_year+2,hold_period_yrs+1),2))
...

Sheet Inputs
B1: Property Analysis — Inputs
B3: All inputs the model needs. Blue cells are editable. The skill writes only to this tab. Italic-gray rows = source / provenance (auto-populated).
B5: Input | C5: Value | D5: Note
B6: Property
B7: Property Address | C7: 1417 S Canal St, Pittsburgh, PA 15215 | D7: Full street address as provided by the prompt.
B8: ZIP Code | C8: 15215 | D8: Parsed from address; drives HUD FMR + SAFMR lookup.
B9: Bedrooms | C9: 3 | D9: Drives FMR lookup by bedroom count.
B10: Bathrooms | C10: 1
B11: Beds — Source | C11: Joe override | D11: WPRDC / RentCast / prompt / override.
B13: Deal Particulars
B14: Purchase Price | C14: 130000
B15: Purchase Price — Source | C15: Wholesaler quote (off-market) | D15: Wholesaler quote / MLS / Joe's offer.
B16: ARV (After-Repair Value) | C16: 255000
B17: ARV — Source | C17: Joe override / wholesaler quote | D17: RentCast comps / appraisal / manual.
B18: Rehab Cost | C18: 55000
B19: Closing Cost (% of price) | C19: 0.07
B20: Holding Period (months) | C20: 3 | D20: Months between acquisition and rent-ready.
B22: Acquisition Line Items (one-time, capitalized into LP basis)
B23: Wholesaler Fee | C23: 7000 | D23: 0 if direct off-market or MLS.
B24: Inspection Fee | C24: 350
B25: Appraisal Fee | C25: 750
B26: Holding-Period Utilities / Mo | C26: 500 | D26: Owner-paid tax/ins/util carry during rehab.
B28: Financing — Acquisition
B29: Down Payment (% of price) | C29: 1 | D29: 1.0 = all cash; 0.20 = 20% down.
B30: Interest Rate | C30: 0.095
B31: Loan Term (yrs) | C31: 30
B33: Financing — Refinance (BRRRR)
B34: Refi Year (0 = no refi) | C34: 3
B35: Refi LTV (% of ARV) | C35: 0.75
B36: Refi Interest Rate | C36: 0.075
B37: Refi Term (yrs) | C37: 30
B38: Refi Closing Cost (% of loan) | C38: 0.04
B40: Operating — Rent (Section 8 oriented)
B41: Underwriting Rent (monthly) | C41: 2500 | D41: HUD FMR for Section 8 tenancies.
B42: Rent — Source | C42: Joe override: $2,500 (HUD FMR FY2026 would be $1,670) | D42: HUD FMR / SAFMR / RentCast / override.
B43: Market Rent (open-market comp) | C43: 2300 | D43: Informational only; for variance check vs underwriting rent.
B44: Market Rent — Source | C44: RentCast comparable (fixture mode) | D44: RentCast / Zillow / manual.
B45: Annual Rent Growth | C45: 0.04 | D45: Section 8 follows HUD reset; 3% historical.
B46: Vacancy Rate | C46: 0.04 | D46: Section 8 typically lower than market.
B48: Operating — Variable Expenses (% of gross rent)
...

Sheet Cashflow
B1: Cashflow
B4: Year | C4: 0 | D4: 1 | E4: 2 | F4: 3 | G4: 4 | H4: 5 | I4: 6 | J4: 7 | K4: 8 | L4: 9 | M4: 10 | N4: 11 | O4: 12 | P4: 13 | Q4: 14 | R4: 15
B6: Revenue
B7: Gross Rent | C7: =IF(OR(C$4<1,C$4>hold_period_yrs),0,monthly_rent*12*(1+rent_growth)^(C$4-1)) | D7: =IF(OR(D$4<1,D$4>hold_period_yrs),0,monthly_rent*12*(1+rent_growth)^(D$4-1)) | E7: =IF(OR(E$4<1,E$4>hold_period_yrs),0,monthly_rent*12*(1+rent_growth)^(E$4-1)) | F7: =IF(OR(F$4<1,F$4>hold_period_yrs),0,monthly_rent*12*(1+rent_growth)^(F$4-1)) | G7: =IF(OR(G$4<1,G$4>hold_period_yrs),0,monthly_rent*12*(1+rent_growth)^(G$4-1)) | H7: =IF(OR(H$4<1,H$4>hold_period_yrs),0,monthly_rent*12*(1+rent_growth)^(H$4-1)) | I7: =IF(OR(I$4<1,I$4>hold_period_yrs),0,monthly_rent*12*(1+rent_growth)^(I$4-1)) | J7: =IF(OR(J$4<1,J$4>hold_period_yrs),0,monthly_rent*12*(1+rent_growth)^(J$4-1)) | ... R7: =IF(OR(R$4<1,R$4>hold_period_yrs),0,monthly_rent*12*(1+rent_growth)^(R$4-1))
B8: Vacancy Loss | C8: =IF(OR(C$4<1,C$4>hold_period_yrs),0,-C7*vacancy_rate) | D8: =IF(OR(D$4<1,D$4>hold_period_yrs),0,-D7*vacancy_rate) | E8: =IF(OR(E$4<1,E$4>hold_period_yrs),0,-E7*vacancy_rate) | F8: =IF(OR(F$4<1,F$4>hold_period_yrs),0,-F7*vacancy_rate) | G8: =IF(OR(G$4<1,G$4>hold_period_yrs),0,-G7*vacancy_rate) | H8: =IF(OR(H$4<1,H$4>hold_period_yrs),0,-H7*vacancy_rate) | I8: =IF(OR(I$4<1,I$4>hold_period_yrs),0,-I7*vacancy_rate) | J8: =IF(OR(J$4<1,J$4>hold_period_yrs),0,-J7*vacancy_rate) | ... R8: =IF(OR(R$4<1,R$4>hold_period_yrs),0,-R7*vacancy_rate)
B9: Effective Gross Income | C9: =IF(OR(C$4<1,C$4>hold_period_yrs),0,C7+C8) | D9: =IF(OR(D$4<1,D$4>hold_period_yrs),0,D7+D8) | E9: =IF(OR(E$4<1,E$4>hold_period_yrs),0,E7+E8) | F9: =IF(OR(F$4<1,F$4>hold_period_yrs),0,F7+F8) | G9: =IF(OR(G$4<1,G$4>hold_period_yrs),0,G7+G8) | H9: =IF(OR(H$4<1,H$4>hold_period_yrs),0,H7+H8) | I9: =IF(OR(I$4<1,I$4>hold_period_yrs),0,I7+I8) | J9: =IF(OR(J$4<1,J$4>hold_period_yrs),0,J7+J8) | ... R9: =IF(OR(R$4<1,R$4>hold_period_yrs),0,R7+R8)
B11: Operating Expenses — Variable
B12: Management | C12: =IF(OR(C$4<1,C$4>hold_period_yrs),0,-C7*management_pct) | D12: =IF(OR(D$4<1,D$4>hold_period_yrs),0,-D7*management_pct) | E12: =IF(OR(E$4<1,E$4>hold_period_yrs),0,-E7*management_pct) | F12: =IF(OR(F$4<1,F$4>hold_period_yrs),0,-F7*management_pct) | G12: =IF(OR(G$4<1,G$4>hold_period_yrs),0,-G7*management_pct) | H12: =IF(OR(H$4<1,H$4>hold_period_yrs),0,-H7*management_pct) | I12: =IF(OR(I$4<1,I$4>hold_period_yrs),0,-I7*management_pct) | J12: =IF(OR(J$4<1,J$4>hold_period_yrs),0,-J7*management_pct) | ... R12: =IF(OR(R$4<1,R$4>hold_period_yrs),0,-R7*management_pct)
B13: Maintenance | C13: =IF(OR(C$4<1,C$4>hold_period_yrs),0,-C7*maintenance_pct) | D13: =IF(OR(D$4<1,D$4>hold_period_yrs),0,-D7*maintenance_pct) | E13: =IF(OR(E$4<1,E$4>hold_period_yrs),0,-E7*maintenance_pct) | F13: =IF(OR(F$4<1,F$4>hold_period_yrs),0,-F7*maintenance_pct) | G13: =IF(OR(G$4<1,G$4>hold_period_yrs),0,-G7*maintenance_pct) | H13: =IF(OR(H$4<1,H$4>hold_period_yrs),0,-H7*maintenance_pct) | I13: =IF(OR(I$4<1,I$4>hold_period_yrs),0,-I7*maintenance_pct) | J13: =IF(OR(J$4<1,J$4>hold_period_yrs),0,-J7*maintenance_pct) | ... R13: =IF(OR(R$4<1,R$4>hold_period_yrs),0,-R7*maintenance_pct)
B14: CapEx Reserve | C14: =IF(OR(C$4<1,C$4>hold_period_yrs),0,-C7*capex_reserve_pct) | D14: =IF(OR(D$4<1,D$4>hold_period_yrs),0,-D7*capex_reserve_pct) | E14: =IF(OR(E$4<1,E$4>hold_period_yrs),0,-E7*capex_reserve_pct) | F14: =IF(OR(F$4<1,F$4>hold_period_yrs),0,-F7*capex_reserve_pct) | G14: =IF(OR(G$4<1,G$4>hold_period_yrs),0,-G7*capex_reserve_pct) | H14: =IF(OR(H$4<1,H$4>hold_period_yrs),0,-H7*capex_reserve_pct) | I14: =IF(OR(I$4<1,I$4>hold_period_yrs),0,-I7*capex_reserve_pct) | J14: =IF(OR(J$4<1,J$4>hold_period_yrs),0,-J7*capex_reserve_pct) | ... R14: =IF(OR(R$4<1,R$4>hold_period_yrs),0,-R7*capex_reserve_pct)
B16: Operating Expenses — Fixed
B17: Property Tax | C17: =IF(OR(C$4<1,C$4>hold_period_yrs),0,-property_tax_annual*(1+expense_growth)^(C$4-1)) | D17: =IF(OR(D$4<1,D$4>hold_period_yrs),0,-property_tax_annual*(1+expense_growth)^(D$4-1)) | E17: =IF(OR(E$4<1,E$4>hold_period_yrs),0,-property_tax_annual*(1+expense_growth)^(E$4-1)) | F17: =IF(OR(F$4<1,F$4>hold_period_yrs),0,-property_tax_annual*(1+expense_growth)^(F$4-1)) | G17: =IF(OR(G$4<1,G$4>hold_period_yrs),0,-property_tax_annual*(1+expense_growth)^(G$4-1)) | H17: =IF(OR(H$4<1,H$4>hold_period_yrs),0,-property_tax_annual*(1+expense_growth)^(H$4-1)) | I17: =IF(OR(I$4<1,I$4>hold_period_yrs),0,-property_tax_annual*(1+expense_growth)^(I$4-1)) | J17: =IF(OR(J$4<1,J$4>hold_period_yrs),0,-property_tax_annual*(1+expense_growth)^(J$4-1)) | ... R17: =IF(OR(R$4<1,R$4>hold_period_yrs),0,-property_tax_annual*(1+expense_growth)^(R$4-1))
B18: Insurance | C18: =IF(OR(C$4<1,C$4>hold_period_yrs),0,-insurance_annual*(1+expense_growth)^(C$4-1)) | D18: =IF(OR(D$4<1,D$4>hold_period_yrs),0,-insurance_annual*(1+expense_growth)^(D$4-1)) | E18: =IF(OR(E$4<1,E$4>hold_period_yrs),0,-insurance_annual*(1+expense_growth)^(E$4-1)) | F18: =IF(OR(F$4<1,F$4>hold_period_yrs),0,-insurance_annual*(1+expense_growth)^(F$4-1)) | G18: =IF(OR(G$4<1,G$4>hold_period_yrs),0,-insurance_annual*(1+expense_growth)^(G$4-1)) | H18: =IF(OR(H$4<1,H$4>hold_period_yrs),0,-insurance_annual*(1+expense_growth)^(H$4-1)) | I18: =IF(OR(I$4<1,I$4>hold_period_yrs),0,-insurance_annual*(1+expense_growth)^(I$4-1)) | J18: =IF(OR(J$4<1,J$4>hold_period_yrs),0,-insurance_annual*(1+expense_growth)^(J$4-1)) | ... R18: =IF(OR(R$4<1,R$4>hold_period_yrs),0,-insurance_annual*(1+expense_growth)^(R$4-1))
B19: Utilities | C19: =IF(OR(C$4<1,C$4>hold_period_yrs),0,-utilities_annual*(1+expense_growth)^(C$4-1)) | D19: =IF(OR(D$4<1,D$4>hold_period_yrs),0,-utilities_annual*(1+expense_growth)^(D$4-1)) | E19: =IF(OR(E$4<1,E$4>hold_period_yrs),0,-utilities_annual*(1+expense_growth)^(E$4-1)) | F19: =IF(OR(F$4<1,F$4>hold_period_yrs),0,-utilities_annual*(1+expense_growth)^(F$4-1)) | G19: =IF(OR(G$4<1,G$4>hold_period_yrs),0,-utilities_annual*(1+expense_growth)^(G$4-1)) | H19: =IF(OR(H$4<1,H$4>hold_period_yrs),0,-utilities_annual*(1+expense_growth)^(H$4-1)) | I19: =IF(OR(I$4<1,I$4>hold_period_yrs),0,-utilities_annual*(1+expense_growth)^(I$4-1)) | J19: =IF(OR(J$4<1,J$4>hold_period_yrs),0,-utilities_annual*(1+expense_growth)^(J$4-1)) | ... R19: =IF(OR(R$4<1,R$4>hold_period_yrs),0,-utilities_annual*(1+expense_growth)^(R$4-1))
B20: HOA / Other | C20: =IF(OR(C$4<1,C$4>hold_period_yrs),0,-hoa_annual*(1+expense_growth)^(C$4-1)) | D20: =IF(OR(D$4<1,D$4>hold_period_yrs),0,-hoa_annual*(1+expense_growth)^(D$4-1)) | E20: =IF(OR(E$4<1,E$4>hold_period_yrs),0,-hoa_annual*(1+expense_growth)^(E$4-1)) | F20: =IF(OR(F$4<1,F$4>hold_period_yrs),0,-hoa_annual*(1+expense_growth)^(F$4-1)) | G20: =IF(OR(G$4<1,G$4>hold_period_yrs),0,-hoa_annual*(1+expense_growth)^(G$4-1)) | H20: =IF(OR(H$4<1,H$4>hold_period_yrs),0,-hoa_annual*(1+expense_growth)^(H$4-1)) | I20: =IF(OR(I$4<1,I$4>hold_period_yrs),0,-hoa_annual*(1+expense_growth)^(I$4-1)) | J20: =IF(OR(J$4<1,J$4>hold_period_yrs),0,-hoa_annual*(1+expense_growth)^(J$4-1)) | ... R20: =IF(OR(R$4<1,R$4>hold_period_yrs),0,-hoa_annual*(1+expense_growth)^(R$4-1))
B22: Net Operating Income | C22: =IF(OR(C$4<1,C$4>hold_period_yrs),0,C9+C12+C13+C14+C17+C18+C19+C20) | D22: =IF(OR(D$4<1,D$4>hold_period_yrs),0,D9+D12+D13+D14+D17+D18+D19+D20) | E22: =IF(OR(E$4<1,E$4>hold_period_yrs),0,E9+E12+E13+E14+E17+E18+E19+E20) | F22: =IF(OR(F$4<1,F$4>hold_period_yrs),0,F9+F12+F13+F14+F17+F18+F19+F20) | G22: =IF(OR(G$4<1,G$4>hold_period_yrs),0,G9+G12+G13+G14+G17+G18+G19+G20) | H22: =IF(OR(H$4<1,H$4>hold_period_yrs),0,H9+H12+H13+H14+H17+H18+H19+H20) | I22: =IF(OR(I$4<1,I$4>hold_period_yrs),0,I9+I12+I13+I14+I17+I18+I19+I20) | J22: =IF(OR(J$4<1,J$4>hold_period_yrs),0,J9+J12+J13+J14+J17+J18+J19+J20) | ... R22: =IF(OR(R$4<1,R$4>hold_period_yrs),0,R9+R12+R13+R14+R17+R18+R19+R20)
B24: Debt Service
B25: Active Loan Principal | C25: =IF(OR(C$4<1,C$4>hold_period_yrs),0,IF(AND(refi_year>0,C$4>=refi_year),arv*refi_ltv,purchase_price*(1-down_payment_pct))) | D25: =IF(OR(D$4<1,D$4>hold_period_yrs),0,IF(AND(refi_year>0,D$4>=refi_year),arv*refi_ltv,purchase_price*(1-down_payment_pct))) | E25: =IF(OR(E$4<1,E$4>hold_period_yrs),0,IF(AND(refi_year>0,E$4>=refi_year),arv*refi_ltv,purchase_price*(1-down_payment_pct))) | F25: =IF(OR(F$4<1,F$4>hold_period_yrs),0,IF(AND(refi_year>0,F$4>=refi_year),arv*refi_ltv,purchase_price*(1-down_payment_pct))) | G25: =IF(OR(G$4<1,G$4>hold_period_yrs),0,IF(AND(refi_year>0,G$4>=refi_year),arv*refi_ltv,purchase_price*(1-down_payment_pct))) | H25: =IF(OR(H$4<1,H$4>hold_period_yrs),0,IF(AND(refi_year>0,H$4>=refi_year),arv*refi_ltv,purchase_price*(1-down_payment_pct))) | I25: =IF(OR(I$4<1,I$4>hold_period_yrs),0,IF(AND(refi_year>0,I$4>=refi_year),arv*refi_ltv,purchase_price*(1-down_payment_pct))) | J25: =IF(OR(J$4<1,J$4>hold_period_yrs),0,IF(AND(refi_year>0,J$4>=refi_year),arv*refi_ltv,purchase_price*(1-down_payment_pct))) | ... R25: =IF(OR(R$4<1,R$4>hold_period_yrs),0,IF(AND(refi_year>0,R$4>=refi_year),arv*refi_ltv,purchase_price*(1-down_payment_pct)))
B26: Active Interest Rate | C26: =IF(OR(C$4<1,C$4>hold_period_yrs),0,IF(AND(refi_year>0,C$4>=refi_year),refi_interest_rate,interest_rate)) | D26: =IF(OR(D$4<1,D$4>hold_period_yrs),0,IF(AND(refi_year>0,D$4>=refi_year),refi_interest_rate,interest_rate)) | E26: =IF(OR(E$4<1,E$4>hold_period_yrs),0,IF(AND(refi_year>0,E$4>=refi_year),refi_interest_rate,interest_rate)) | F26: =IF(OR(F$4<1,F$4>hold_period_yrs),0,IF(AND(refi_year>0,F$4>=refi_year),refi_interest_rate,interest_rate)) | G26: =IF(OR(G$4<1,G$4>hold_period_yrs),0,IF(AND(refi_year>0,G$4>=refi_year),refi_interest_rate,interest_rate)) | H26: =IF(OR(H$4<1,H$4>hold_period_yrs),0,IF(AND(refi_year>0,H$4>=refi_year),refi_interest_rate,interest_rate)) | I26: =IF(OR(I$4<1,I$4>hold_period_yrs),0,IF(AND(refi_year>0,I$4>=refi_year),refi_interest_rate,interest_rate)) | J26: =IF(OR(J$4<1,J$4>hold_period_yrs),0,IF(AND(refi_year>0,J$4>=refi_year),refi_interest_rate,interest_rate)) | ... R26: =IF(OR(R$4<1,R$4>hold_period_yrs),0,IF(AND(refi_year>0,R$4>=refi_year),refi_interest_rate,interest_rate))
B27: Active Loan Term (yrs) | C27: =IF(OR(C$4<1,C$4>hold_period_yrs),0,IF(AND(refi_year>0,C$4>=refi_year),refi_term_yrs,loan_term_yrs)) | D27: =IF(OR(D$4<1,D$4>hold_period_yrs),0,IF(AND(refi_year>0,D$4>=refi_year),refi_term_yrs,loan_term_yrs)) | E27: =IF(OR(E$4<1,E$4>hold_period_yrs),0,IF(AND(refi_year>0,E$4>=refi_year),refi_term_yrs,loan_term_yrs)) | F27: =IF(OR(F$4<1,F$4>hold_period_yrs),0,IF(AND(refi_year>0,F$4>=refi_year),refi_term_yrs,loan_term_yrs)) | G27: =IF(OR(G$4<1,G$4>hold_period_yrs),0,IF(AND(refi_year>0,G$4>=refi_year),refi_term_yrs,loan_term_yrs)) | H27: =IF(OR(H$4<1,H$4>hold_period_yrs),0,IF(AND(refi_year>0,H$4>=refi_year),refi_term_yrs,loan_term_yrs)) | I27: =IF(OR(I$4<1,I$4>hold_period_yrs),0,IF(AND(refi_year>0,I$4>=refi_year),refi_term_yrs,loan_term_yrs)) | J27: =IF(OR(J$4<1,J$4>hold_period_yrs),0,IF(AND(refi_year>0,J$4>=refi_year),refi_term_yrs,loan_term_yrs)) | ... R27: =IF(OR(R$4<1,R$4>hold_period_yrs),0,IF(AND(refi_year>0,R$4>=refi_year),refi_term_yrs,loan_term_yrs))
B28: Monthly Payment | C28: =IF(OR(C$4<1,C$4>hold_period_yrs),0,IFERROR(-PMT(C26/12,C27*12,C25),0)) | D28: =IF(OR(D$4<1,D$4>hold_period_yrs),0,IFERROR(-PMT(D26/12,D27*12,D25),0)) | E28: =IF(OR(E$4<1,E$4>hold_period_yrs),0,IFERROR(-PMT(E26/12,E27*12,E25),0)) | F28: =IF(OR(F$4<1,F$4>hold_period_yrs),0,IFERROR(-PMT(F26/12,F27*12,F25),0)) | G28: =IF(OR(G$4<1,G$4>hold_period_yrs),0,IFERROR(-PMT(G26/12,G27*12,G25),0)) | H28: =IF(OR(H$4<1,H$4>hold_period_yrs),0,IFERROR(-PMT(H26/12,H27*12,H25),0)) | I28: =IF(OR(I$4<1,I$4>hold_period_yrs),0,IFERROR(-PMT(I26/12,I27*12,I25),0)) | J28: =IF(OR(J$4<1,J$4>hold_period_yrs),0,IFERROR(-PMT(J26/12,J27*12,J25),0)) | ... R28: =IF(OR(R$4<1,R$4>hold_period_yrs),0,IFERROR(-PMT(R26/12,R27*12,R25),0))
B29: Annual Debt Service | C29: =IF(OR(C$4<1,C$4>hold_period_yrs),0,-C28*12) | D29: =IF(OR(D$4<1,D$4>hold_period_yrs),0,-D28*12) | E29: =IF(OR(E$4<1,E$4>hold_period_yrs),0,-E28*12) | F29: =IF(OR(F$4<1,F$4>hold_period_yrs),0,-F28*12) | G29: =IF(OR(G$4<1,G$4>hold_period_yrs),0,-G28*12) | H29: =IF(OR(H$4<1,H$4>hold_period_yrs),0,-H28*12) | I29: =IF(OR(I$4<1,I$4>hold_period_yrs),0,-I28*12) | J29: =IF(OR(J$4<1,J$4>hold_period_yrs),0,-J28*12) | ... R29: =IF(OR(R$4<1,R$4>hold_period_yrs),0,-R28*12)
B31: Operating Cash Flow | C31: =IF(OR(C$4<1,C$4>hold_period_yrs),0,C22+C29) | D31: =IF(OR(D$4<1,D$4>hold_period_yrs),0,D22+D29) | E31: =IF(OR(E$4<1,E$4>hold_period_yrs),0,E22+E29) | F31: =IF(OR(F$4<1,F$4>hold_period_yrs),0,F22+F29) | G31: =IF(OR(G$4<1,G$4>hold_period_yrs),0,G22+G29) | H31: =IF(OR(H$4<1,H$4>hold_period_yrs),0,H22+H29) | I31: =IF(OR(I$4<1,I$4>hold_period_yrs),0,I22+I29) | J31: =IF(OR(J$4<1,J$4>hold_period_yrs),0,J22+J29) | ... R31: =IF(OR(R$4<1,R$4>hold_period_yrs),0,R22+R29)
B33: Capital Flows
B34: Acquisition Cost | C34: =IF(C$4=0,-(purchase_price*down_payment_pct+purchase_price*closing_cost_pct+rehab_cost+wholesaler_fee+inspection_fee+appraisal_fee+(IFERROR(-PMT(interest_rate/12,loan_term_yrs*12,purchase_price*(1-down_payment_pct)),0)+property_tax_annual/12+insurance_annual/12+holding_utilities_monthly+utilities_annual/12)*holding_months),0) | D34: =IF(D$4=0,-(purchase_price*down_payment_pct+purchase_price*closing_cost_pct+rehab_cost+wholesaler_fee+inspection_fee+appraisal_fee+(IFERROR(-PMT(interest_rate/12,loan_term_yrs*12,purchase_price*(1-down_payment_pct)),0)+property_tax_annual/12+insurance_annual/12+holding_utilities_monthly+utilities_annual/12)*holding_months),0) | E34: =IF(E$4=0,-(purchase_price*down_payment_pct+purchase_price*closing_cost_pct+rehab_cost+wholesaler_fee+inspection_fee+appraisal_fee+(IFERROR(-PMT(interest_rate/12,loan_term_yrs*12,purchase_price*(1-down_payment_pct)),0)+property_tax_annual/12+insurance_annual/12+holding_utilities_monthly+utilities_annual/12)*holding_months),0) | F34: =IF(F$4=0,-(purchase_price*down_payment_pct+purchase_price*closing_cost_pct+rehab_cost+wholesaler_fee+inspection_fee+appraisal_fee+(IFERROR(-PMT(interest_rate/12,loan_term_yrs*12,purchase_price*(1-down_payment_pct)),0)+property_tax_annual/12+insurance_annual/12+holding_utilities_monthly+utilities_annual/12)*holding_months),0) | G34: =IF(G$4=0,-(purchase_price*down_payment_pct+purchase_price*closing_cost_pct+rehab_cost+wholesaler_fee+inspection_fee+appraisal_fee+(IFERROR(-PMT(interest_rate/12,loan_term_yrs*12,purchase_price*(1-down_payment_pct)),0)+property_tax_annual/12+insurance_annual/12+holding_utilities_monthly+utilities_annual/12)*holding_months),0) | H34: =IF(H$4=0,-(purchase_price*down_payment_pct+purchase_price*closing_cost_pct+rehab_cost+wholesaler_fee+inspection_fee+appraisal_fee+(IFERROR(-PMT(interest_rate/12,loan_term_yrs*12,purchase_price*(1-down_payment_pct)),0)+property_tax_annual/12+insurance_annual/12+holding_utilities_monthly+utilities_annual/12)*holding_months),0) | I34: =IF(I$4=0,-(purchase_price*down_payment_pct+purchase_price*closing_cost_pct+rehab_cost+wholesaler_fee+inspection_fee+appraisal_fee+(IFERROR(-PMT(interest_rate/12,loan_term_yrs*12,purchase_price*(1-down_payment_pct)),0)+property_tax_annual/12+insurance_annual/12+holding_utilities_monthly+utilities_annual/12)*holding_months),0) | J34: =IF(J$4=0,-(purchase_price*down_payment_pct+purchase_price*closing_cost_pct+rehab_cost+wholesaler_fee+inspection_fee+appraisal_fee+(IFERROR(-PMT(interest_rate/12,loan_term_yrs*12,purchase_price*(1-down_payment_pct)),0)+property_tax_annual/12+insurance_annual/12+holding_utilities_monthly+utilities_annual/12)*holding_months),0) | ... R34: =IF(R$4=0,-(purchase_price*down_payment_pct+purchase_price*closing_cost_pct+rehab_cost+wholesaler_fee+inspection_fee+appraisal_fee+(IFERROR(-PMT(interest_rate/12,loan_term_yrs*12,purchase_price*(1-down_payment_pct)),0)+property_tax_annual/12+insurance_annual/12+holding_utilities_monthly+utilities_annual/12)*holding_months),0)
B35: Refi Cash-Out | C35: =IF(AND(refi_year>0,C$4=refi_year),(arv*refi_ltv) - IFERROR(ABS(FV(interest_rate/12,refi_year*12,-(IFERROR(-PMT(interest_rate/12,loan_term_yrs*12,purchase_price*(1-down_payment_pct)),0)),purchase_price*(1-down_payment_pct))),purchase_price*(1-down_payment_pct)) - (arv*refi_ltv*refi_closing_cost_pct),0) | D35: =IF(AND(refi_year>0,D$4=refi_year),(arv*refi_ltv) - IFERROR(ABS(FV(interest_rate/12,refi_year*12,-(IFERROR(-PMT(interest_rate/12,loan_term_yrs*12,purchase_price*(1-down_payment_pct)),0)),purchase_price*(1-down_payment_pct))),purchase_price*(1-down_payment_pct)) - (arv*refi_ltv*refi_closing_cost_pct),0) | E35: =IF(AND(refi_year>0,E$4=refi_year),(arv*refi_ltv) - IFERROR(ABS(FV(interest_rate/12,refi_year*12,-(IFERROR(-PMT(interest_rate/12,loan_term_yrs*12,purchase_price*(1-down_payment_pct)),0)),purchase_price*(1-down_payment_pct))),purchase_price*(1-down_payment_pct)) - (arv*refi_ltv*refi_closing_cost_pct),0) | F35: =IF(AND(refi_year>0,F$4=refi_year),(arv*refi_ltv) - IFERROR(ABS(FV(interest_rate/12,refi_year*12,-(IFERROR(-PMT(interest_rate/12,loan_term_yrs*12,purchase_price*(1-down_payment_pct)),0)),purchase_price*(1-down_payment_pct))),purchase_price*(1-down_payment_pct)) - (arv*refi_ltv*refi_closing_cost_pct),0) | G35: =IF(AND(refi_year>0,G$4=refi_year),(arv*refi_ltv) - IFERROR(ABS(FV(interest_rate/12,refi_year*12,-(IFERROR(-PMT(interest_rate/12,loan_term_yrs*12,purchase_price*(1-down_payment_pct)),0)),purchase_price*(1-down_payment_pct))),purchase_price*(1-down_payment_pct)) - (arv*refi_ltv*refi_closing_cost_pct),0) | H35: =IF(AND(refi_year>0,H$4=refi_year),(arv*refi_ltv) - IFERROR(ABS(FV(interest_rate/12,refi_year*12,-(IFERROR(-PMT(interest_rate/12,loan_term_yrs*12,purchase_price*(1-down_payment_pct)),0)),purchase_price*(1-down_payment_pct))),purchase_price*(1-down_payment_pct)) - (arv*refi_ltv*refi_closing_cost_pct),0) | I35: =IF(AND(refi_year>0,I$4=refi_year),(arv*refi_ltv) - IFERROR(ABS(FV(interest_rate/12,refi_year*12,-(IFERROR(-PMT(interest_rate/12,loan_term_yrs*12,purchase_price*(1-down_payment_pct)),0)),purchase_price*(1-down_payment_pct))),purchase_price*(1-down_payment_pct)) - (arv*refi_ltv*refi_closing_cost_pct),0) | J35: =IF(AND(refi_year>0,J$4=refi_year),(arv*refi_ltv) - IFERROR(ABS(FV(interest_rate/12,refi_year*12,-(IFERROR(-PMT(interest_rate/12,loan_term_yrs*12,purchase_price*(1-down_payment_pct)),0)),purchase_price*(1-down_payment_pct))),purchase_price*(1-down_payment_pct)) - (arv*refi_ltv*refi_closing_cost_pct),0) | ... R35: =IF(AND(refi_year>0,R$4=refi_year),(arv*refi_ltv) - IFERROR(ABS(FV(interest_rate/12,refi_year*12,-(IFERROR(-PMT(interest_rate/12,loan_term_yrs*12,purchase_price*(1-down_payment_pct)),0)),purchase_price*(1-down_payment_pct))),purchase_price*(1-down_payment_pct)) - (arv*refi_ltv*refi_closing_cost_pct),0)
B36: Exit Proceeds (Net) | C36: =IF(C$4=hold_period_yrs,(C22*(1+rent_growth)/exit_cap_rate)*(1-cost_of_sale_pct) - IFERROR(ABS(FV(C26/12,IF(refi_year>0,hold_period_yrs-refi_year+1,hold_period_yrs)*12,-C28,C25)),0),0) | D36: =IF(D$4=hold_period_yrs,(D22*(1+rent_growth)/exit_cap_rate)*(1-cost_of_sale_pct) - IFERROR(ABS(FV(D26/12,IF(refi_year>0,hold_period_yrs-refi_year+1,hold_period_yrs)*12,-D28,D25)),0),0) | E36: =IF(E$4=hold_period_yrs,(E22*(1+rent_growth)/exit_cap_rate)*(1-cost_of_sale_pct) - IFERROR(ABS(FV(E26/12,IF(refi_year>0,hold_period_yrs-refi_year+1,hold_period_yrs)*12,-E28,E25)),0),0) | F36: =IF(F$4=hold_period_yrs,(F22*(1+rent_growth)/exit_cap_rate)*(1-cost_of_sale_pct) - IFERROR(ABS(FV(F26/12,IF(refi_year>0,hold_period_yrs-refi_year+1,hold_period_yrs)*12,-F28,F25)),0),0) | G36: =IF(G$4=hold_period_yrs,(G22*(1+rent_growth)/exit_cap_rate)*(1-cost_of_sale_pct) - IFERROR(ABS(FV(G26/12,IF(refi_year>0,hold_period_yrs-refi_year+1,hold_period_yrs)*12,-G28,G25)),0),0) | H36: =IF(H$4=hold_period_yrs,(H22*(1+rent_growth)/exit_cap_rate)*(1-cost_of_sale_pct) - IFERROR(ABS(FV(H26/12,IF(refi_year>0,hold_period_yrs-refi_year+1,hold_period_yrs)*12,-H28,H25)),0),0) | I36: =IF(I$4=hold_period_yrs,(I22*(1+rent_growth)/exit_cap_rate)*(1-cost_of_sale_pct) - IFERROR(ABS(FV(I26/12,IF(refi_year>0,hold_period_yrs-refi_year+1,hold_period_yrs)*12,-I28,I25)),0),0) | J36: =IF(J$4=hold_period_yrs,(J22*(1+rent_growth)/exit_cap_rate)*(1-cost_of_sale_pct) - IFERROR(ABS(FV(J26/12,IF(refi_year>0,hold_period_yrs-refi_year+1,hold_period_yrs)*12,-J28,J25)),0),0) | ... R36: =IF(R$4=hold_period_yrs,(R22*(1+rent_growth)/exit_cap_rate)*(1-cost_of_sale_pct) - IFERROR(ABS(FV(R26/12,IF(refi_year>0,hold_period_yrs-refi_year+1,hold_period_yrs)*12,-R28,R25)),0),0)
B38: Net Cash Flow | C38: =IF(C$4>hold_period_yrs,0,C22+C29+C34+C35+C36) | D38: =IF(D$4>hold_period_yrs,0,D22+D29+D34+D35+D36) | E38: =IF(E$4>hold_period_yrs,0,E22+E29+E34+E35+E36) | F38: =IF(F$4>hold_period_yrs,0,F22+F29+F34+F35+F36) | G38: =IF(G$4>hold_period_yrs,0,G22+G29+G34+G35+G36) | H38: =IF(H$4>hold_period_yrs,0,H22+H29+H34+H35+H36) | I38: =IF(I$4>hold_period_yrs,0,I22+I29+I34+I35+I36) | J38: =IF(J$4>hold_period_yrs,0,J22+J29+J34+J35+J36) | ... R38: =IF(R$4>hold_period_yrs,0,R22+R29+R34+R35+R36)
B39: DSCR | C39: =IF(OR(C$4<1,C$4>hold_period_yrs,C29=0),"",IFERROR(C22/-C29,"")) | D39: =IF(OR(D$4<1,D$4>hold_period_yrs,D29=0),"",IFERROR(D22/-D29,"")) | E39: =IF(OR(E$4<1,E$4>hold_period_yrs,E29=0),"",IFERROR(E22/-E29,"")) | F39: =IF(OR(F$4<1,F$4>hold_period_yrs,F29=0),"",IFERROR(F22/-F29,"")) | G39: =IF(OR(G$4<1,G$4>hold_period_yrs,G29=0),"",IFERROR(G22/-G29,"")) | H39: =IF(OR(H$4<1,H$4>hold_period_yrs,H29=0),"",IFERROR(H22/-H29,"")) | I39: =IF(OR(I$4<1,I$4>hold_period_yrs,I29=0),"",IFERROR(I22/-I29,"")) | J39: =IF(OR(J$4<1,J$4>hold_period_yrs,J29=0),"",IFERROR(J22/-J29,"")) | ... R39: =IF(OR(R$4<1,R$4>hold_period_yrs,R29=0),"",IFERROR(R22/-R29,""))
B41: Equity Tracking
B42: Property Value | C42: =IF(C$4=0,purchase_price+rehab_cost,IF(C$4>hold_period_yrs,0,arv*(1+appreciation_rate)^(C$4-1))) | D42: =IF(D$4=0,purchase_price+rehab_cost,IF(D$4>hold_period_yrs,0,arv*(1+appreciation_rate)^(D$4-1))) | E42: =IF(E$4=0,purchase_price+rehab_cost,IF(E$4>hold_period_yrs,0,arv*(1+appreciation_rate)^(E$4-1))) | F42: =IF(F$4=0,purchase_price+rehab_cost,IF(F$4>hold_period_yrs,0,arv*(1+appreciation_rate)^(F$4-1))) | G42: =IF(G$4=0,purchase_price+rehab_cost,IF(G$4>hold_period_yrs,0,arv*(1+appreciation_rate)^(G$4-1))) | H42: =IF(H$4=0,purchase_price+rehab_cost,IF(H$4>hold_period_yrs,0,arv*(1+appreciation_rate)^(H$4-1))) | I42: =IF(I$4=0,purchase_price+rehab_cost,IF(I$4>hold_period_yrs,0,arv*(1+appreciation_rate)^(I$4-1))) | J42: =IF(J$4=0,purchase_price+rehab_cost,IF(J$4>hold_period_yrs,0,arv*(1+appreciation_rate)^(J$4-1))) | ... R42: =IF(R$4=0,purchase_price+rehab_cost,IF(R$4>hold_period_yrs,0,arv*(1+appreciation_rate)^(R$4-1)))
B43: Outstanding Loan Balance (EOP) | C43: =IF(C$4=0,purchase_price*(1-down_payment_pct),IF(C$4>hold_period_yrs,0,IF(AND(refi_year>0,C$4>=refi_year),IFERROR(ABS(FV(refi_interest_rate/12,(C$4-refi_year+1)*12,-(IFERROR(-PMT(refi_interest_rate/12,refi_term_yrs*12,arv*refi_ltv),0)),arv*refi_ltv)),0),IFERROR(ABS(FV(interest_rate/12,C$4*12,-(IFERROR(-PMT(interest_rate/12,loan_term_yrs*12,purchase_price*(1-down_payment_pct)),0)),purchase_price*(1-down_payment_pct))),0)))) | D43: =IF(D$4=0,purchase_price*(1-down_payment_pct),IF(D$4>hold_period_yrs,0,IF(AND(refi_year>0,D$4>=refi_year),IFERROR(ABS(FV(refi_interest_rate/12,(D$4-refi_year+1)*12,-(IFERROR(-PMT(refi_interest_rate/12,refi_term_yrs*12,arv*refi_ltv),0)),arv*refi_ltv)),0),IFERROR(ABS(FV(interest_rate/12,D$4*12,-(IFERROR(-PMT(interest_rate/12,loan_term_yrs*12,purchase_price*(1-down_payment_pct)),0)),purchase_price*(1-down_payment_pct))),0)))) | E43: =IF(E$4=0,purchase_price*(1-down_payment_pct),IF(E$4>hold_period_yrs,0,IF(AND(refi_year>0,E$4>=refi_year),IFERROR(ABS(FV(refi_interest_rate/12,(E$4-refi_year+1)*12,-(IFERROR(-PMT(refi_interest_rate/12,refi_term_yrs*12,arv*refi_ltv),0)),arv*refi_ltv)),0),IFERROR(ABS(FV(interest_rate/12,E$4*12,-(IFERROR(-PMT(interest_rate/12,loan_term_yrs*12,purchase_price*(1-down_payment_pct)),0)),purchase_price*(1-down_payment_pct))),0)))) | F43: =IF(F$4=0,purchase_price*(1-down_payment_pct),IF(F$4>hold_period_yrs,0,IF(AND(refi_year>0,F$4>=refi_year),IFERROR(ABS(FV(refi_interest_rate/12,(F$4-refi_year+1)*12,-(IFERROR(-PMT(refi_interest_rate/12,refi_term_yrs*12,arv*refi_ltv),0)),arv*refi_ltv)),0),IFERROR(ABS(FV(interest_rate/12,F$4*12,-(IFERROR(-PMT(interest_rate/12,loan_term_yrs*12,purchase_price*(1-down_payment_pct)),0)),purchase_price*(1-down_payment_pct))),0)))) | G43: =IF(G$4=0,purchase_price*(1-down_payment_pct),IF(G$4>hold_period_yrs,0,IF(AND(refi_year>0,G$4>=refi_year),IFERROR(ABS(FV(refi_interest_rate/12,(G$4-refi_year+1)*12,-(IFERROR(-PMT(refi_interest_rate/12,refi_term_yrs*12,arv*refi_ltv),0)),arv*refi_ltv)),0),IFERROR(ABS(FV(interest_rate/12,G$4*12,-(IFERROR(-PMT(interest_rate/12,loan_term_yrs*12,purchase_price*(1-down_payment_pct)),0)),purchase_price*(1-down_payment_pct))),0)))) | H43: =IF(H$4=0,purchase_price*(1-down_payment_pct),IF(H$4>hold_period_yrs,0,IF(AND(refi_year>0,H$4>=refi_year),IFERROR(ABS(FV(refi_interest_rate/12,(H$4-refi_year+1)*12,-(IFERROR(-PMT(refi_interest_rate/12,refi_term_yrs*12,arv*refi_ltv),0)),arv*refi_ltv)),0),IFERROR(ABS(FV(interest_rate/12,H$4*12,-(IFERROR(-PMT(interest_rate/12,loan_term_yrs*12,purchase_price*(1-down_payment_pct)),0)),purchase_price*(1-down_payment_pct))),0)))) | I43: =IF(I$4=0,purchase_price*(1-down_payment_pct),IF(I$4>hold_period_yrs,0,IF(AND(refi_year>0,I$4>=refi_year),IFERROR(ABS(FV(refi_interest_rate/12,(I$4-refi_year+1)*12,-(IFERROR(-PMT(refi_interest_rate/12,refi_term_yrs*12,arv*refi_ltv),0)),arv*refi_ltv)),0),IFERROR(ABS(FV(interest_rate/12,I$4*12,-(IFERROR(-PMT(interest_rate/12,loan_term_yrs*12,purchase_price*(1-down_payment_pct)),0)),purchase_price*(1-down_payment_pct))),0)))) | J43: =IF(J$4=0,purchase_price*(1-down_payment_pct),IF(J$4>hold_period_yrs,0,IF(AND(refi_year>0,J$4>=refi_year),IFERROR(ABS(FV(refi_interest_rate/12,(J$4-refi_year+1)*12,-(IFERROR(-PMT(refi_interest_rate/12,refi_term_yrs*12,arv*refi_ltv),0)),arv*refi_ltv)),0),IFERROR(ABS(FV(interest_rate/12,J$4*12,-(IFERROR(-PMT(interest_rate/12,loan_term_yrs*12,purchase_price*(1-down_payment_pct)),0)),purchase_price*(1-down_payment_pct))),0)))) | ... R43: =IF(R$4=0,purchase_price*(1-down_payment_pct),IF(R$4>hold_period_yrs,0,IF(AND(refi_year>0,R$4>=refi_year),IFERROR(ABS(FV(refi_interest_rate/12,(R$4-refi_year+1)*12,-(IFERROR(-PMT(refi_interest_rate/12,refi_term_yrs*12,arv*refi_ltv),0)),arv*refi_ltv)),0),IFERROR(ABS(FV(interest_rate/12,R$4*12,-(IFERROR(-PMT(interest_rate/12,loan_term_yrs*12,purchase_price*(1-down_payment_pct)),0)),purchase_price*(1-down_payment_pct))),0))))
B44: Equity Value | C44: =IF(C$4>hold_period_yrs,0,C42-C43) | D44: =IF(D$4>hold_period_yrs,0,D42-D43) | E44: =IF(E$4>hold_period_yrs,0,E42-E43) | F44: =IF(F$4>hold_period_yrs,0,F42-F43) | G44: =IF(G$4>hold_period_yrs,0,G42-G43) | H44: =IF(H$4>hold_period_yrs,0,H42-H43) | I44: =IF(I$4>hold_period_yrs,0,I42-I43) | J44: =IF(J$4>hold_period_yrs,0,J42-J43) | ... R44: =IF(R$4>hold_period_yrs,0,R42-R43)
B46: LP / GP Distribution (Joe's Split)
B47: LP Distribution | C47: =C38 | D47: =IF(OR(D$4<1,D$4>hold_period_yrs),0,MIN(MAX(0,D38),MAX(0,(-C38)-0))+MAX(0,MAX(0,D38)-MAX(0,(-C38)-0))*gp_lp_split_lp) | E47: =IF(OR(E$4<1,E$4>hold_period_yrs),0,MIN(MAX(0,E38),MAX(0,(-C38)-SUM(D47:D47)))+MAX(0,MAX(0,E38)-MAX(0,(-C38)-SUM(D47:D47)))*gp_lp_split_lp) | F47: =IF(OR(F$4<1,F$4>hold_period_yrs),0,MIN(MAX(0,F38),MAX(0,(-C38)-SUM(D47:E47)))+MAX(0,MAX(0,F38)-MAX(0,(-C38)-SUM(D47:E47)))*gp_lp_split_lp) | G47: =IF(OR(G$4<1,G$4>hold_period_yrs),0,MIN(MAX(0,G38),MAX(0,(-C38)-SUM(D47:F47)))+MAX(0,MAX(0,G38)-MAX(0,(-C38)-SUM(D47:F47)))*gp_lp_split_lp) | H47: =IF(OR(H$4<1,H$4>hold_period_yrs),0,MIN(MAX(0,H38),MAX(0,(-C38)-SUM(D47:G47)))+MAX(0,MAX(0,H38)-MAX(0,(-C38)-SUM(D47:G47)))*gp_lp_split_lp) | I47: =IF(OR(I$4<1,I$4>hold_period_yrs),0,MIN(MAX(0,I38),MAX(0,(-C38)-SUM(D47:H47)))+MAX(0,MAX(0,I38)-MAX(0,(-C38)-SUM(D47:H47)))*gp_lp_split_lp) | J47: =IF(OR(J$4<1,J$4>hold_period_yrs),0,MIN(MAX(0,J38),MAX(0,(-C38)-SUM(D47:I47)))+MAX(0,MAX(0,J38)-MAX(0,(-C38)-SUM(D47:I47)))*gp_lp_split_lp) | K47: =IF(OR(K$4<1,K$4>hold_period_yrs),0,MIN(MAX(0,K38),MAX(0,(-C38)-SUM(D47:J47)))+MAX(0,MAX(0,K38)-MAX(0,(-C38)-SUM(D47:J47)))*gp_lp_split_lp) | L47: =IF(OR(L$4<1,L$4>hold_period_yrs),0,MIN(MAX(0,L38),MAX(0,(-C38)-SUM(D47:K47)))+MAX(0,MAX(0,L38)-MAX(0,(-C38)-SUM(D47:K47)))*gp_lp_split_lp) | M47: =IF(OR(M$4<1,M$4>hold_period_yrs),0,MIN(MAX(0,M38),MAX(0,(-C38)-SUM(D47:L47)))+MAX(0,MAX(0,M38)-MAX(0,(-C38)-SUM(D47:L47)))*gp_lp_split_lp) | N47: =IF(OR(N$4<1,N$4>hold_period_yrs),0,MIN(MAX(0,N38),MAX(0,(-C38)-SUM(D47:M47)))+MAX(0,MAX(0,N38)-MAX(0,(-C38)-SUM(D47:M47)))*gp_lp_split_lp) | O47: =IF(OR(O$4<1,O$4>hold_period_yrs),0,MIN(MAX(0,O38),MAX(0,(-C38)-SUM(D47:N47)))+MAX(0,MAX(0,O38)-MAX(0,(-C38)-SUM(D47:N47)))*gp_lp_split_lp) | P47: =IF(OR(P$4<1,P$4>hold_period_yrs),0,MIN(MAX(0,P38),MAX(0,(-C38)-SUM(D47:O47)))+MAX(0,MAX(0,P38)-MAX(0,(-C38)-SUM(D47:O47)))*gp_lp_split_lp) | Q47: =IF(OR(Q$4<1,Q$4>hold_period_yrs),0,MIN(MAX(0,Q38),MAX(0,(-C38)-SUM(D47:P47)))+MAX(0,MAX(0,Q38)-MAX(0,(-C38)-SUM(D47:P47)))*gp_lp_split_lp) | R47: =IF(OR(R$4<1,R$4>hold_period_yrs),0,MIN(MAX(0,R38),MAX(0,(-C38)-SUM(D47:Q47)))+MAX(0,MAX(0,R38)-MAX(0,(-C38)-SUM(D47:Q47)))*gp_lp_split_lp)
B48: GP Distribution | C48: =0 | D48: =IF(OR(D$4<1,D$4>hold_period_yrs),0,MAX(0,MAX(0,D38)-MAX(0,(-C38)-0))*(1-gp_lp_split_lp)) | E48: =IF(OR(E$4<1,E$4>hold_period_yrs),0,MAX(0,MAX(0,E38)-MAX(0,(-C38)-SUM(D47:D47)))*(1-gp_lp_split_lp)) | F48: =IF(OR(F$4<1,F$4>hold_period_yrs),0,MAX(0,MAX(0,F38)-MAX(0,(-C38)-SUM(D47:E47)))*(1-gp_lp_split_lp)) | G48: =IF(OR(G$4<1,G$4>hold_period_yrs),0,MAX(0,MAX(0,G38)-MAX(0,(-C38)-SUM(D47:F47)))*(1-gp_lp_split_lp)) | H48: =IF(OR(H$4<1,H$4>hold_period_yrs),0,MAX(0,MAX(0,H38)-MAX(0,(-C38)-SUM(D47:G47)))*(1-gp_lp_split_lp)) | I48: =IF(OR(I$4<1,I$4>hold_period_yrs),0,MAX(0,MAX(0,I38)-MAX(0,(-C38)-SUM(D47:H47)))*(1-gp_lp_split_lp)) | J48: =IF(OR(J$4<1,J$4>hold_period_yrs),0,MAX(0,MAX(0,J38)-MAX(0,(-C38)-SUM(D47:I47)))*(1-gp_lp_split_lp)) | K48: =IF(OR(K$4<1,K$4>hold_period_yrs),0,MAX(0,MAX(0,K38)-MAX(0,(-C38)-SUM(D47:J47)))*(1-gp_lp_split_lp)) | L48: =IF(OR(L$4<1,L$4>hold_period_yrs),0,MAX(0,MAX(0,L38)-MAX(0,(-C38)-SUM(D47:K47)))*(1-gp_lp_split_lp)) | M48: =IF(OR(M$4<1,M$4>hold_period_yrs),0,MAX(0,MAX(0,M38)-MAX(0,(-C38)-SUM(D47:L47)))*(1-gp_lp_split_lp)) | N48: =IF(OR(N$4<1,N$4>hold_period_yrs),0,MAX(0,MAX(0,N38)-MAX(0,(-C38)-SUM(D47:M47)))*(1-gp_lp_split_lp)) | O48: =IF(OR(O$4<1,O$4>hold_period_yrs),0,MAX(0,MAX(0,O38)-MAX(0,(-C38)-SUM(D47:N47)))*(1-gp_lp_split_lp)) | P48: =IF(OR(P$4<1,P$4>hold_period_yrs),0,MAX(0,MAX(0,P38)-MAX(0,(-C38)-SUM(D47:O47)))*(1-gp_lp_split_lp)) | Q48: =IF(OR(Q$4<1,Q$4>hold_period_yrs),0,MAX(0,MAX(0,Q38)-MAX(0,(-C38)-SUM(D47:P47)))*(1-gp_lp_split_lp)) | R48: =IF(OR(R$4<1,R$4>hold_period_yrs),0,MAX(0,MAX(0,R38)-MAX(0,(-C38)-SUM(D47:Q47)))*(1-gp_lp_split_lp))

Sheet Sources
B1: Sources & Provenance
B3: Where every load-bearing number came from. Filled by the Python engine on each run. The Excel model uses values from the Inputs tab; this tab is the audit trail.
B5: Field | C5: Value | D5: Source | E5: Confidence | F5: Note
B6: Inputs
B7: Property Address | C7: 1417 S Canal St, Pittsburgh, PA 15215 | D7: prompt | E7: high
B8: ZIP Code | C8: 15215 | D8: parsed from address | E8: high
B9: Bedrooms | C9: 3 | D9: override | E9: high
B10: Bathrooms | C10: 1 | D10: default | E10: low
B11: Purchase Price | C11: 130000 | D11: wholesaler quote | E11: high
B12: ARV | C12: 255000 | D12: Joe override | E12: high
B13: Rehab Cost | C13: 55000 | D13: Joe estimate | E13: medium
B14: Monthly Rent (underwriting) | C14: 2500 | D14: Joe override | E14: high | F14: Section 8 voucher; FMR-fallback would be $1,670 for 3BR ZCTA 15215.
B15: Market Rent (comparable) | C15: 2300 | D15: RentCast comp | E15: medium
B16: Property Tax (annual) | C16: 3249 | D16: Joe override | E16: high
B17: Insurance (annual) | C17: 1020 | D17: industry default | E17: medium
B19: Reference Data Freshness
B20: HUD FMR vintage | C20: FY2026 | F20: FY of HUD FMR database in use.
B21: HUD SAFMR vintage | F21: FY of HUD SAFMR database (if used).
B22: Geo (Census ZCTA-county) | C22: Census 2020 ZCTA-county | F22: Census ZCTA-county vintage.
B23: WPRDC (Allegheny County) | C23: Allegheny County (live ArcGIS) | F23: WPRDC parcel data tax-year and as-of date.
B24: Allegheny millage tax year | C24: TAX_YEAR=2025 | F24: Local millage rate vintage.
B25: RentCast mode | C25: off | F25: off / fixture / live.
B26: Report generated at | C26: 2026-05-18 11:43:53 | F26: Run timestamp.
B28: Blockers / Warnings

Sheet Audit
B1: Audit Checks
B3: Check | C3: Expected | D3: Actual | E3: Status | F3: Notes
B4: A. Workbook Health
B5: Purchase price is positive | C5: >0 | D5: =purchase_price | E5: =IF(purchase_price>0,"PASS","FAIL") | F5: Purchase price must be a positive number.
B6: ARV is positive | C6: >0 | D6: =arv | E6: =IF(arv>0,"PASS","FAIL") | F6: After-repair value must be a positive number.
B7: Monthly rent is positive | C7: >0 | D7: =monthly_rent | E7: =IF(monthly_rent>0,"PASS","FAIL") | F7: Rent must be > 0 for the model to produce returns.
B8: Hold period is at least 1 year | C8: >=1 | D8: =hold_period_yrs | E8: =IF(hold_period_yrs>=1,"PASS","FAIL") | F8: Cannot model a zero-year hold.
B9: Down payment between 0 and 100% | C9: 0 to 1 | D9: =down_payment_pct | E9: =IF(AND(down_payment_pct>=0,down_payment_pct<=1),"PASS","FAIL") | F9: 1.0 = all cash; 0.20 = 20% down.
B10: Refi LTV between 0 and 90% | C10: 0 to 0.90 | D10: =refi_ltv | E10: =IF(AND(refi_ltv>=0,refi_ltv<=0.90),"PASS","WARN") | F10: >90% LTV is unusual for SFH refi; verify lender.
B12: B. Sign Convention
B13: Year 1 Gross Rent is positive | C13: >0 | D13: ='Cashflow'!D7 | E13: =IF('Cashflow'!D7>0,"PASS","FAIL") | F13: Rent comes through as positive cash inflow.
B14: Year 1 Property Tax is negative (or zero) | C14: <=0 | D14: ='Cashflow'!D17 | E14: =IF('Cashflow'!D17<=0,"PASS","FAIL") | F14: Expenses display as negative.
B15: Year 1 Debt Service is negative or zero | C15: <=0 | D15: ='Cashflow'!D29 | E15: =IF('Cashflow'!D29<=0,"PASS","FAIL") | F15: Debt payments are cash outflows.
B16: Year 0 cash flow is negative (capital outlay) | C16: <0 | D16: ='Cashflow'!C38 | E16: =IF('Cashflow'!C38<0,"PASS","FAIL") | F16: Acquisition is a cash outflow.
B18: C. Tie-Outs
B19: Year 1 NOI ties to EGI + OpEx | C19: =ROUND('Cashflow'!D9+'Cashflow'!D12+'Cashflow'!D13+'Cashflow'!D14+'Cashflow'!D17+'Cashflow'!D18+'Cashflow'!D19+'Cashflow'!D20,2) | D19: =ROUND('Cashflow'!D22,2) | E19: =IF(ROUND('Cashflow'!D22,2)=ROUND('Cashflow'!D9+'Cashflow'!D12+'Cashflow'!D13+'Cashflow'!D14+'Cashflow'!D17+'Cashflow'!D18+'Cashflow'!D19+'Cashflow'!D20,2),"PASS","FAIL") | F19: Year 1 NOI must equal EGI plus all operating expenses.
B20: Year 1 Operating Cash Flow = NOI + Debt Service | C20: =ROUND('Cashflow'!D22+'Cashflow'!D29,2) | D20: =ROUND('Cashflow'!D31,2) | E20: =IF(ROUND('Cashflow'!D31,2)=ROUND('Cashflow'!D22+'Cashflow'!D29,2),"PASS","FAIL") | F20: Operating CF is NOI net of debt service (no capital flows).
B21: Year 1 Equity Value = Property Value − Loan Balance | C21: =ROUND('Cashflow'!D42-'Cashflow'!D43,2) | D21: =ROUND('Cashflow'!D44,2) | E21: =IF(ROUND('Cashflow'!D44,2)=ROUND('Cashflow'!D42-'Cashflow'!D43,2),"PASS","FAIL") | F21: Equity = Property Value minus what's still owed to the lender.
B22: Year 0 acquisition cash matches inputs | C22: =-(purchase_price*down_payment_pct + purchase_price*closing_cost_pct + rehab_cost + wholesaler_fee + inspection_fee + appraisal_fee + (IFERROR(-PMT(interest_rate/12,loan_term_yrs*12,purchase_price*(1-down_payment_pct)),0)+property_tax_annual/12+insurance_annual/12+holding_utilities_monthly+utilities_annual/12)*holding_months) | D22: ='Cashflow'!C34 | E22: =IF(ROUND('Cashflow'!C34,2)=ROUND(-(purchase_price*down_payment_pct + purchase_price*closing_cost_pct + rehab_cost + wholesaler_fee + inspection_fee + appraisal_fee + (IFERROR(-PMT(interest_rate/12,loan_term_yrs*12,purchase_price*(1-down_payment_pct)),0)+property_tax_annual/12+insurance_annual/12+holding_utilities_monthly+utilities_annual/12)*holding_months),2),"PASS","FAIL") | F22: Year 0 outflow = down + closing + rehab + fees + carry.
B24: D. Economic Sanity
B25: Refi cash-out is non-negative (or refi disabled) | C25: >=0 | D25: =IF(refi_year=0,0,SUM('Cashflow'!C35:'Cashflow'!R35)) | E25: =IF(OR(refi_year=0,SUM('Cashflow'!C35:'Cashflow'!R35)>=0),"PASS","WARN") | F25: If refi cash-out is negative, the refi is uneconomic.
B26: Exit proceeds are positive | C26: >0 | D26: =SUM('Cashflow'!C36:'Cashflow'!R36) | E26: =IF(SUM('Cashflow'!C36:'Cashflow'!R36)>0,"PASS","WARN") | F26: Net of debt and cost of sale, the exit should be positive.
B27: At least one year of DSCR ≥ min threshold | C27: =dscr_min | D27: =IFERROR(MIN('Cashflow'!D39:'Cashflow'!R39),"n/a") | E27: =IF(COUNT('Cashflow'!D39:'Cashflow'!R39)=0,"WARN",IF(MIN('Cashflow'!D39:'Cashflow'!R39)>=dscr_min,"PASS","FAIL")) | F27: At least one operating year must meet the DSCR threshold.
B28: Year-N property value > Purchase Price | C28: >purchase_price | D28: =INDEX('Cashflow'!C42:'Cashflow'!R42,hold_period_yrs+1) | E28: =IF(INDEX('Cashflow'!C42:'Cashflow'!R42,hold_period_yrs+1)>purchase_price,"PASS","WARN") | F28: Otherwise the hold has produced no appreciation.
B30: E. Rent & Market Sanity
B31: Underwriting rent within 50% of market comparable | C31: |diff| < 50% | D31: =IFERROR(IF(market_rent=0,"n/a — no market comp",(market_rent-monthly_rent)/monthly_rent),"n/a") | E31: =IF(market_rent=0,"WARN",IFERROR(IF(ABS((market_rent-monthly_rent)/monthly_rent)<0.5,"PASS","WARN"),"WARN")) | F31: Large variance suggests rent override needs review.
B33: F. Threshold Sanity
B34: Cap rate threshold is reasonable (3-15%) | C34: 0.03 to 0.15 | D34: =cap_rate_min | E34: =IF(AND(cap_rate_min>=0.03,cap_rate_min<=0.15),"PASS","WARN") | F34: Most SFH investors target 7-10%.
B35: DSCR threshold is reasonable (1.0-1.5x) | C35: 1.0 to 1.5 | D35: =dscr_min | E35: =IF(AND(dscr_min>=1.0,dscr_min<=1.5),"PASS","WARN") | F35: Lenders typically require 1.20-1.25x DSCR.
